2025-10-01 15:48:31,401 [INFO] job_applications.settings: Logging configuration applied successfully
2025-10-01 15:48:31,403 [DEBUG] environ.environ: get 'CELERY_BROKER_URL' casted as 'None' with default 'redis://job_app_redis:6379/0'
2025-10-01 15:48:31,404 [DEBUG] environ.environ: get 'CELERY_RESULT_BACKEND' casted as 'None' with default 'redis://job_app_redis:6379/0'
2025-10-01 15:48:31,594 [INFO] job_applications.settings: Logging configuration applied successfully
2025-10-01 15:48:31,594 [INFO] job_applications.settings: Logging configuration applied successfully
2025-10-01 15:48:31,596 [DEBUG] environ.environ: get 'CELERY_BROKER_URL' casted as 'None' with default 'redis://job_app_redis:6379/0'
2025-10-01 15:48:31,596 [DEBUG] environ.environ: get 'CELERY_BROKER_URL' casted as 'None' with default 'redis://job_app_redis:6379/0'
2025-10-01 15:48:31,598 [DEBUG] environ.environ: get 'CELERY_RESULT_BACKEND' casted as 'None' with default 'redis://job_app_redis:6379/0'
2025-10-01 15:48:31,598 [DEBUG] environ.environ: get 'CELERY_RESULT_BACKEND' casted as 'None' with default 'redis://job_app_redis:6379/0'
2025-10-01 15:49:04,999 [DEBUG] celery.utils.functional: 
def chord(self, header, body, partial_args=0, interval=1, countdown=2, max_retries=3, eager=4, **kwargs):
    return 1

2025-10-01 15:49:04,999 [DEBUG] celery.utils.functional: 
def chord(self, header, body, partial_args=0, interval=1, countdown=2, max_retries=3, eager=4, **kwargs):
    return 1

2025-10-01 15:49:05,001 [DEBUG] celery.utils.functional: 
def chunks(task, it, n):
    return 1

2025-10-01 15:49:05,002 [DEBUG] celery.utils.functional: 
def chunks(task, it, n):
    return 1

2025-10-01 15:49:05,004 [DEBUG] celery.utils.functional: 
def process_large_resume_batch(self, job_requisition_id, tenant_id, document_type, applications_data, num_candidates, role=0, branch=1, authorization_header=2):
    return 1

2025-10-01 15:49:05,004 [DEBUG] celery.utils.functional: 
def process_large_resume_batch(self, job_requisition_id, tenant_id, document_type, applications_data, num_candidates, role=0, branch=1, authorization_header=2):
    return 1

2025-10-01 15:49:05,006 [DEBUG] celery.utils.functional: 
def unlock_chord(self, group_id, callback, interval=0, max_retries=1, result=2, Result=3, GroupResult=4, result_from_tuple=5, **kwargs):
    return 1

2025-10-01 15:49:05,007 [DEBUG] celery.utils.functional: 
def unlock_chord(self, group_id, callback, interval=0, max_retries=1, result=2, Result=3, GroupResult=4, result_from_tuple=5, **kwargs):
    return 1

2025-10-01 15:49:05,008 [DEBUG] celery.utils.functional: 
def send_notification_task(self, applicant_data, tenant_id, event_type, employment_gaps=0):
    return 1

2025-10-01 15:49:05,010 [DEBUG] celery.utils.functional: 
def send_notification_task(self, applicant_data, tenant_id, event_type, employment_gaps=0):
    return 1

2025-10-01 15:49:05,011 [DEBUG] celery.utils.functional: 
def aggregate_screening_results(self, chunk_results, job_requisition_id, tenant_id, num_candidates, document_type, authorization_header=0):
    return 1

2025-10-01 15:49:05,012 [DEBUG] celery.utils.functional: 
def screen_resumes_task(job_requisition_id, document_type, num_candidates, applications_data, job_requisition):
    return 1

2025-10-01 15:49:05,013 [DEBUG] celery.utils.functional: 
def process_resume_chunk(self, job_requisition_id, tenant_id, document_type, applications_chunk, chunk_index, total_chunks, role=0, branch=1, authorization_header=2, job_requirements=3):
    return 1

2025-10-01 15:49:05,015 [DEBUG] celery.utils.functional: 
def aggregate_screening_results(self, chunk_results, job_requisition_id, tenant_id, num_candidates, document_type, authorization_header=0):
    return 1

2025-10-01 15:49:05,015 [DEBUG] celery.utils.functional: 
def group(self, tasks, result, group_id, partial_args, add_to_parent=0):
    return 1

2025-10-01 15:49:05,017 [DEBUG] celery.utils.functional: 
def process_resume_chunk(self, job_requisition_id, tenant_id, document_type, applications_chunk, chunk_index, total_chunks, role=0, branch=1, authorization_header=2, job_requirements=3):
    return 1

2025-10-01 15:49:05,017 [DEBUG] celery.utils.functional: 
def xmap(task, it):
    return 1

2025-10-01 15:49:05,019 [DEBUG] celery.utils.functional: 
def backend_cleanup():
    return 1

2025-10-01 15:49:05,021 [DEBUG] celery.utils.functional: 
def group(self, tasks, result, group_id, partial_args, add_to_parent=0):
    return 1

2025-10-01 15:49:05,021 [DEBUG] celery.utils.functional: 
def chain(*args, **kwargs):
    return 1

2025-10-01 15:49:05,023 [DEBUG] celery.utils.functional: 
def xmap(task, it):
    return 1

2025-10-01 15:49:05,023 [DEBUG] celery.utils.functional: 
def auto_screen_all_applications():
    return 1

2025-10-01 15:49:05,025 [DEBUG] celery.utils.functional: 
def backend_cleanup():
    return 1

2025-10-01 15:49:05,025 [DEBUG] celery.utils.functional: 
def xstarmap(task, it):
    return 1

2025-10-01 15:49:05,027 [DEBUG] celery.utils.functional: 
def chain(*args, **kwargs):
    return 1

2025-10-01 15:49:05,027 [DEBUG] celery.utils.functional: 
def screen_resumes_task(job_requisition_id, document_type, num_candidates, applications_data, job_requisition):
    return 1

2025-10-01 15:49:05,029 [DEBUG] celery.utils.functional: 
def xstarmap(task, it):
    return 1

2025-10-01 15:49:05,029 [DEBUG] celery.utils.functional: 
def accumulate(self, *args, **kwargs):
    return 1

2025-10-01 15:49:05,031 [DEBUG] celery.utils.functional: 
def accumulate(self, *args, **kwargs):
    return 1

2025-10-01 15:49:05,033 [DEBUG] celery.utils.functional: 
def auto_screen_all_applications():
    return 1

2025-10-01 16:31:02,658 [INFO] job_applications: Entering MicroserviceRS256JWTMiddleware
2025-10-01 16:31:02,674 [INFO] job_applications: Fetching public key from: http://auth-service:8001/api/public-key/1f530d5313654d8781aaab5ea0de2065/?tenant_id=3
2025-10-01 16:31:02,709 [DEBUG] urllib3.connectionpool: Starting new HTTP connection (1): auth-service:8001
2025-10-01 16:31:02,768 [DEBUG] urllib3.connectionpool: http://auth-service:8001 "GET /api/public-key/1f530d5313654d8781aaab5ea0de2065/?tenant_id=3 HTTP/1.1" 200 477
2025-10-01 16:31:02,839 [DEBUG] urllib3.connectionpool: Starting new HTTP connection (1): auth-service:8001
2025-10-01 16:31:02,934 [DEBUG] urllib3.connectionpool: http://auth-service:8001 "GET /api/tenant/tenants/09145372-eb5d-40ff-9d93-ca49425a16e6/ HTTP/1.1" 200 428
2025-10-01 16:31:02,939 [INFO] job_applications: Set schema to: proliance
2025-10-01 16:31:35,219 [WARNING] django.request: Method Not Allowed: /api/applications-engine/applications/job-requisitions/PRO-0003/applications/
2025-10-01 16:31:35,219 [WARNING] django.request: Method Not Allowed: /api/applications-engine/applications/job-requisitions/PRO-0003/applications/
2025-10-01 16:31:35,259 [INFO] job_applications: Entering MicroserviceRS256JWTMiddleware
2025-10-01 16:31:35,262 [INFO] job_applications: Fetching public key from: http://auth-service:8001/api/public-key/1f530d5313654d8781aaab5ea0de2065/?tenant_id=3
2025-10-01 16:31:35,267 [DEBUG] urllib3.connectionpool: Starting new HTTP connection (1): auth-service:8001
2025-10-01 16:31:35,311 [DEBUG] urllib3.connectionpool: http://auth-service:8001 "GET /api/public-key/1f530d5313654d8781aaab5ea0de2065/?tenant_id=3 HTTP/1.1" 200 477
2025-10-01 16:31:35,316 [DEBUG] urllib3.connectionpool: Starting new HTTP connection (1): auth-service:8001
2025-10-01 16:31:35,363 [DEBUG] urllib3.connectionpool: http://auth-service:8001 "GET /api/tenant/tenants/09145372-eb5d-40ff-9d93-ca49425a16e6/ HTTP/1.1" 200 428
2025-10-01 16:31:35,365 [INFO] job_applications: Set schema to: proliance
2025-10-01 16:31:35,413 [INFO] job_applications: Entering MicroserviceRS256JWTMiddleware
2025-10-01 16:31:35,415 [INFO] job_applications: Fetching public key from: http://auth-service:8001/api/public-key/1f530d5313654d8781aaab5ea0de2065/?tenant_id=3
2025-10-01 16:31:35,419 [DEBUG] urllib3.connectionpool: Starting new HTTP connection (1): auth-service:8001
2025-10-01 16:31:35,454 [DEBUG] urllib3.connectionpool: http://auth-service:8001 "GET /api/public-key/1f530d5313654d8781aaab5ea0de2065/?tenant_id=3 HTTP/1.1" 200 477
2025-10-01 16:31:35,459 [DEBUG] urllib3.connectionpool: Starting new HTTP connection (1): auth-service:8001
2025-10-01 16:31:35,500 [DEBUG] urllib3.connectionpool: http://auth-service:8001 "GET /api/tenant/tenants/09145372-eb5d-40ff-9d93-ca49425a16e6/ HTTP/1.1" 200 428
2025-10-01 16:31:35,502 [INFO] job_applications: Set schema to: proliance
2025-10-01 16:31:35,653 [ERROR] django.request: Internal Server Error: /api/applications-engine/applications/job-requisitions/PRO-0003/applications/
Traceback (most recent call last):
  File "/usr/local/lib/python3.11/site-packages/django/db/backends/utils.py", line 105, in _execute
    return self.cursor.execute(sql, params)
           ^^^^^^^^^^^^^^^^^^^^^^^^^^^^^^^^
psycopg2.errors.UndefinedTable: relation "job_applications_job_application" does not exist
LINE 1: SELECT COUNT(*) AS "__count" FROM "job_applications_job_appl...
                                          ^


The above exception was the direct cause of the following exception:

Traceback (most recent call last):
  File "/usr/local/lib/python3.11/site-packages/django/core/handlers/exception.py", line 55, in inner
    response = get_response(request)
               ^^^^^^^^^^^^^^^^^^^^^
  File "/usr/local/lib/python3.11/site-packages/django/core/handlers/base.py", line 197, in _get_response
    response = wrapped_callback(request, *callback_args, **callback_kwargs)
               ^^^^^^^^^^^^^^^^^^^^^^^^^^^^^^^^^^^^^^^^^^^^^^^^^^^^^^^^^^^^
  File "/usr/local/lib/python3.11/site-packages/django/views/decorators/csrf.py", line 65, in _view_wrapper
    return view_func(request, *args, **kwargs)
           ^^^^^^^^^^^^^^^^^^^^^^^^^^^^^^^^^^^
  File "/usr/local/lib/python3.11/site-packages/django/views/generic/base.py", line 105, in view
    return self.dispatch(request, *args, **kwargs)
           ^^^^^^^^^^^^^^^^^^^^^^^^^^^^^^^^^^^^^^^
  File "/usr/local/lib/python3.11/site-packages/rest_framework/views.py", line 515, in dispatch
    response = self.handle_exception(exc)
               ^^^^^^^^^^^^^^^^^^^^^^^^^^
  File "/usr/local/lib/python3.11/site-packages/rest_framework/views.py", line 475, in handle_exception
    self.raise_uncaught_exception(exc)
  File "/usr/local/lib/python3.11/site-packages/rest_framework/views.py", line 486, in raise_uncaught_exception
    raise exc
  File "/usr/local/lib/python3.11/site-packages/rest_framework/views.py", line 512, in dispatch
    response = handler(request, *args, **kwargs)
               ^^^^^^^^^^^^^^^^^^^^^^^^^^^^^^^^^
  File "/usr/local/lib/python3.11/site-packages/rest_framework/generics.py", line 203, in get
    return self.list(request, *args, **kwargs)
           ^^^^^^^^^^^^^^^^^^^^^^^^^^^^^^^^^^^
  File "/usr/local/lib/python3.11/site-packages/rest_framework/mixins.py", line 40, in list
    page = self.paginate_queryset(queryset)
           ^^^^^^^^^^^^^^^^^^^^^^^^^^^^^^^^
  File "/usr/local/lib/python3.11/site-packages/rest_framework/generics.py", line 175, in paginate_queryset
    return self.paginator.paginate_queryset(queryset, self.request, view=self)
           ^^^^^^^^^^^^^^^^^^^^^^^^^^^^^^^^^^^^^^^^^^^^^^^^^^^^^^^^^^^^^^^^^^^
  File "/usr/local/lib/python3.11/site-packages/rest_framework/pagination.py", line 211, in paginate_queryset
    self.page = paginator.page(page_number)
                ^^^^^^^^^^^^^^^^^^^^^^^^^^^
  File "/usr/local/lib/python3.11/site-packages/django/core/paginator.py", line 89, in page
    number = self.validate_number(number)
             ^^^^^^^^^^^^^^^^^^^^^^^^^^^^
  File "/usr/local/lib/python3.11/site-packages/django/core/paginator.py", line 70, in validate_number
    if number > self.num_pages:
                ^^^^^^^^^^^^^^
  File "/usr/local/lib/python3.11/site-packages/django/utils/functional.py", line 47, in __get__
    res = instance.__dict__[self.name] = self.func(instance)
                                         ^^^^^^^^^^^^^^^^^^^
  File "/usr/local/lib/python3.11/site-packages/django/core/paginator.py", line 116, in num_pages
    if self.count == 0 and not self.allow_empty_first_page:
       ^^^^^^^^^^
  File "/usr/local/lib/python3.11/site-packages/django/utils/functional.py", line 47, in __get__
    res = instance.__dict__[self.name] = self.func(instance)
                                         ^^^^^^^^^^^^^^^^^^^
  File "/usr/local/lib/python3.11/site-packages/django/core/paginator.py", line 110, in count
    return c()
           ^^^
  File "/usr/local/lib/python3.11/site-packages/django/db/models/query.py", line 604, in count
    return self.query.get_count(using=self.db)
           ^^^^^^^^^^^^^^^^^^^^^^^^^^^^^^^^^^^
  File "/usr/local/lib/python3.11/site-packages/django/db/models/sql/query.py", line 644, in get_count
    return obj.get_aggregation(using, {"__count": Count("*")})["__count"]
           ^^^^^^^^^^^^^^^^^^^^^^^^^^^^^^^^^^^^^^^^^^^^^^^^^^^
  File "/usr/local/lib/python3.11/site-packages/django/db/models/sql/query.py", line 626, in get_aggregation
    result = compiler.execute_sql(SINGLE)
             ^^^^^^^^^^^^^^^^^^^^^^^^^^^^
  File "/usr/local/lib/python3.11/site-packages/django/db/models/sql/compiler.py", line 1623, in execute_sql
    cursor.execute(sql, params)
  File "/usr/local/lib/python3.11/site-packages/django/db/backends/utils.py", line 122, in execute
    return super().execute(sql, params)
           ^^^^^^^^^^^^^^^^^^^^^^^^^^^^
  File "/usr/local/lib/python3.11/site-packages/django/db/backends/utils.py", line 79, in execute
    return self._execute_with_wrappers(
           ^^^^^^^^^^^^^^^^^^^^^^^^^^^^
  File "/usr/local/lib/python3.11/site-packages/django/db/backends/utils.py", line 92, in _execute_with_wrappers
    return executor(sql, params, many, context)
           ^^^^^^^^^^^^^^^^^^^^^^^^^^^^^^^^^^^^
  File "/usr/local/lib/python3.11/site-packages/django/db/backends/utils.py", line 100, in _execute
    with self.db.wrap_database_errors:
  File "/usr/local/lib/python3.11/site-packages/django/db/utils.py", line 91, in __exit__
    raise dj_exc_value.with_traceback(traceback) from exc_value
  File "/usr/local/lib/python3.11/site-packages/django/db/backends/utils.py", line 105, in _execute
    return self.cursor.execute(sql, params)
           ^^^^^^^^^^^^^^^^^^^^^^^^^^^^^^^^
django.db.utils.ProgrammingError: relation "job_applications_job_application" does not exist
LINE 1: SELECT COUNT(*) AS "__count" FROM "job_applications_job_appl...
                                          ^

2025-10-01 16:31:35,653 [ERROR] django.request: Internal Server Error: /api/applications-engine/applications/job-requisitions/PRO-0003/applications/
Traceback (most recent call last):
  File "/usr/local/lib/python3.11/site-packages/django/db/backends/utils.py", line 105, in _execute
    return self.cursor.execute(sql, params)
           ^^^^^^^^^^^^^^^^^^^^^^^^^^^^^^^^
psycopg2.errors.UndefinedTable: relation "job_applications_job_application" does not exist
LINE 1: SELECT COUNT(*) AS "__count" FROM "job_applications_job_appl...
                                          ^


The above exception was the direct cause of the following exception:

Traceback (most recent call last):
  File "/usr/local/lib/python3.11/site-packages/django/core/handlers/exception.py", line 55, in inner
    response = get_response(request)
               ^^^^^^^^^^^^^^^^^^^^^
  File "/usr/local/lib/python3.11/site-packages/django/core/handlers/base.py", line 197, in _get_response
    response = wrapped_callback(request, *callback_args, **callback_kwargs)
               ^^^^^^^^^^^^^^^^^^^^^^^^^^^^^^^^^^^^^^^^^^^^^^^^^^^^^^^^^^^^
  File "/usr/local/lib/python3.11/site-packages/django/views/decorators/csrf.py", line 65, in _view_wrapper
    return view_func(request, *args, **kwargs)
           ^^^^^^^^^^^^^^^^^^^^^^^^^^^^^^^^^^^
  File "/usr/local/lib/python3.11/site-packages/django/views/generic/base.py", line 105, in view
    return self.dispatch(request, *args, **kwargs)
           ^^^^^^^^^^^^^^^^^^^^^^^^^^^^^^^^^^^^^^^
  File "/usr/local/lib/python3.11/site-packages/rest_framework/views.py", line 515, in dispatch
    response = self.handle_exception(exc)
               ^^^^^^^^^^^^^^^^^^^^^^^^^^
  File "/usr/local/lib/python3.11/site-packages/rest_framework/views.py", line 475, in handle_exception
    self.raise_uncaught_exception(exc)
  File "/usr/local/lib/python3.11/site-packages/rest_framework/views.py", line 486, in raise_uncaught_exception
    raise exc
  File "/usr/local/lib/python3.11/site-packages/rest_framework/views.py", line 512, in dispatch
    response = handler(request, *args, **kwargs)
               ^^^^^^^^^^^^^^^^^^^^^^^^^^^^^^^^^
  File "/usr/local/lib/python3.11/site-packages/rest_framework/generics.py", line 203, in get
    return self.list(request, *args, **kwargs)
           ^^^^^^^^^^^^^^^^^^^^^^^^^^^^^^^^^^^
  File "/usr/local/lib/python3.11/site-packages/rest_framework/mixins.py", line 40, in list
    page = self.paginate_queryset(queryset)
           ^^^^^^^^^^^^^^^^^^^^^^^^^^^^^^^^
  File "/usr/local/lib/python3.11/site-packages/rest_framework/generics.py", line 175, in paginate_queryset
    return self.paginator.paginate_queryset(queryset, self.request, view=self)
           ^^^^^^^^^^^^^^^^^^^^^^^^^^^^^^^^^^^^^^^^^^^^^^^^^^^^^^^^^^^^^^^^^^^
  File "/usr/local/lib/python3.11/site-packages/rest_framework/pagination.py", line 211, in paginate_queryset
    self.page = paginator.page(page_number)
                ^^^^^^^^^^^^^^^^^^^^^^^^^^^
  File "/usr/local/lib/python3.11/site-packages/django/core/paginator.py", line 89, in page
    number = self.validate_number(number)
             ^^^^^^^^^^^^^^^^^^^^^^^^^^^^
  File "/usr/local/lib/python3.11/site-packages/django/core/paginator.py", line 70, in validate_number
    if number > self.num_pages:
                ^^^^^^^^^^^^^^
  File "/usr/local/lib/python3.11/site-packages/django/utils/functional.py", line 47, in __get__
    res = instance.__dict__[self.name] = self.func(instance)
                                         ^^^^^^^^^^^^^^^^^^^
  File "/usr/local/lib/python3.11/site-packages/django/core/paginator.py", line 116, in num_pages
    if self.count == 0 and not self.allow_empty_first_page:
       ^^^^^^^^^^
  File "/usr/local/lib/python3.11/site-packages/django/utils/functional.py", line 47, in __get__
    res = instance.__dict__[self.name] = self.func(instance)
                                         ^^^^^^^^^^^^^^^^^^^
  File "/usr/local/lib/python3.11/site-packages/django/core/paginator.py", line 110, in count
    return c()
           ^^^
  File "/usr/local/lib/python3.11/site-packages/django/db/models/query.py", line 604, in count
    return self.query.get_count(using=self.db)
           ^^^^^^^^^^^^^^^^^^^^^^^^^^^^^^^^^^^
  File "/usr/local/lib/python3.11/site-packages/django/db/models/sql/query.py", line 644, in get_count
    return obj.get_aggregation(using, {"__count": Count("*")})["__count"]
           ^^^^^^^^^^^^^^^^^^^^^^^^^^^^^^^^^^^^^^^^^^^^^^^^^^^
  File "/usr/local/lib/python3.11/site-packages/django/db/models/sql/query.py", line 626, in get_aggregation
    result = compiler.execute_sql(SINGLE)
             ^^^^^^^^^^^^^^^^^^^^^^^^^^^^
  File "/usr/local/lib/python3.11/site-packages/django/db/models/sql/compiler.py", line 1623, in execute_sql
    cursor.execute(sql, params)
  File "/usr/local/lib/python3.11/site-packages/django/db/backends/utils.py", line 122, in execute
    return super().execute(sql, params)
           ^^^^^^^^^^^^^^^^^^^^^^^^^^^^
  File "/usr/local/lib/python3.11/site-packages/django/db/backends/utils.py", line 79, in execute
    return self._execute_with_wrappers(
           ^^^^^^^^^^^^^^^^^^^^^^^^^^^^
  File "/usr/local/lib/python3.11/site-packages/django/db/backends/utils.py", line 92, in _execute_with_wrappers
    return executor(sql, params, many, context)
           ^^^^^^^^^^^^^^^^^^^^^^^^^^^^^^^^^^^^
  File "/usr/local/lib/python3.11/site-packages/django/db/backends/utils.py", line 100, in _execute
    with self.db.wrap_database_errors:
  File "/usr/local/lib/python3.11/site-packages/django/db/utils.py", line 91, in __exit__
    raise dj_exc_value.with_traceback(traceback) from exc_value
  File "/usr/local/lib/python3.11/site-packages/django/db/backends/utils.py", line 105, in _execute
    return self.cursor.execute(sql, params)
           ^^^^^^^^^^^^^^^^^^^^^^^^^^^^^^^^
django.db.utils.ProgrammingError: relation "job_applications_job_application" does not exist
LINE 1: SELECT COUNT(*) AS "__count" FROM "job_applications_job_appl...
                                          ^

2025-10-01 16:33:05,606 [INFO] job_applications.settings: Logging configuration applied successfully
2025-10-01 16:33:05,607 [DEBUG] environ.environ: get 'CELERY_BROKER_URL' casted as 'None' with default 'redis://job_app_redis:6379/0'
2025-10-01 16:33:05,608 [DEBUG] environ.environ: get 'CELERY_RESULT_BACKEND' casted as 'None' with default 'redis://job_app_redis:6379/0'
2025-10-01 16:33:11,372 [INFO] job_applications.settings: Logging configuration applied successfully
2025-10-01 16:33:11,373 [DEBUG] environ.environ: get 'CELERY_BROKER_URL' casted as 'None' with default 'redis://job_app_redis:6379/0'
2025-10-01 16:33:11,373 [DEBUG] environ.environ: get 'CELERY_RESULT_BACKEND' casted as 'None' with default 'redis://job_app_redis:6379/0'
2025-10-01 16:33:45,687 [INFO] job_applications: Entering MicroserviceRS256JWTMiddleware
2025-10-01 16:33:45,690 [INFO] job_applications: Fetching public key from: http://auth-service:8001/api/public-key/1f530d5313654d8781aaab5ea0de2065/?tenant_id=3
2025-10-01 16:33:45,693 [DEBUG] urllib3.connectionpool: Starting new HTTP connection (1): auth-service:8001
2025-10-01 16:33:45,740 [DEBUG] urllib3.connectionpool: http://auth-service:8001 "GET /api/public-key/1f530d5313654d8781aaab5ea0de2065/?tenant_id=3 HTTP/1.1" 200 477
2025-10-01 16:33:45,744 [DEBUG] urllib3.connectionpool: Starting new HTTP connection (1): auth-service:8001
2025-10-01 16:33:45,768 [DEBUG] urllib3.connectionpool: http://auth-service:8001 "GET /api/tenant/tenants/09145372-eb5d-40ff-9d93-ca49425a16e6/ HTTP/1.1" 200 428
2025-10-01 16:33:45,770 [INFO] job_applications: Set schema to: proliance
2025-10-01 16:33:45,788 [INFO] job_applications: Entering MicroserviceRS256JWTMiddleware
2025-10-01 16:33:45,789 [INFO] job_applications: Fetching public key from: http://auth-service:8001/api/public-key/1f530d5313654d8781aaab5ea0de2065/?tenant_id=3
2025-10-01 16:33:45,791 [DEBUG] urllib3.connectionpool: Starting new HTTP connection (1): auth-service:8001
2025-10-01 16:33:45,816 [DEBUG] urllib3.connectionpool: http://auth-service:8001 "GET /api/public-key/1f530d5313654d8781aaab5ea0de2065/?tenant_id=3 HTTP/1.1" 200 477
2025-10-01 16:33:45,818 [DEBUG] urllib3.connectionpool: Starting new HTTP connection (1): auth-service:8001
2025-10-01 16:33:45,843 [DEBUG] urllib3.connectionpool: http://auth-service:8001 "GET /api/tenant/tenants/09145372-eb5d-40ff-9d93-ca49425a16e6/ HTTP/1.1" 200 428
2025-10-01 16:33:45,844 [INFO] job_applications: Set schema to: proliance
2025-10-01 16:33:45,894 [ERROR] django.request: Internal Server Error: /api/applications-engine/applications/job-requisitions/PRO-0003/applications/
Traceback (most recent call last):
  File "/usr/local/lib/python3.11/site-packages/django/db/backends/utils.py", line 105, in _execute
    return self.cursor.execute(sql, params)
           ^^^^^^^^^^^^^^^^^^^^^^^^^^^^^^^^
psycopg2.errors.UndefinedTable: relation "job_applications_job_application" does not exist
LINE 1: SELECT COUNT(*) AS "__count" FROM "job_applications_job_appl...
                                          ^


The above exception was the direct cause of the following exception:

Traceback (most recent call last):
  File "/usr/local/lib/python3.11/site-packages/django/core/handlers/exception.py", line 55, in inner
    response = get_response(request)
               ^^^^^^^^^^^^^^^^^^^^^
  File "/usr/local/lib/python3.11/site-packages/django/core/handlers/base.py", line 197, in _get_response
    response = wrapped_callback(request, *callback_args, **callback_kwargs)
               ^^^^^^^^^^^^^^^^^^^^^^^^^^^^^^^^^^^^^^^^^^^^^^^^^^^^^^^^^^^^
  File "/usr/local/lib/python3.11/site-packages/django/views/decorators/csrf.py", line 65, in _view_wrapper
    return view_func(request, *args, **kwargs)
           ^^^^^^^^^^^^^^^^^^^^^^^^^^^^^^^^^^^
  File "/usr/local/lib/python3.11/site-packages/django/views/generic/base.py", line 105, in view
    return self.dispatch(request, *args, **kwargs)
           ^^^^^^^^^^^^^^^^^^^^^^^^^^^^^^^^^^^^^^^
  File "/usr/local/lib/python3.11/site-packages/rest_framework/views.py", line 515, in dispatch
    response = self.handle_exception(exc)
               ^^^^^^^^^^^^^^^^^^^^^^^^^^
  File "/usr/local/lib/python3.11/site-packages/rest_framework/views.py", line 475, in handle_exception
    self.raise_uncaught_exception(exc)
  File "/usr/local/lib/python3.11/site-packages/rest_framework/views.py", line 486, in raise_uncaught_exception
    raise exc
  File "/usr/local/lib/python3.11/site-packages/rest_framework/views.py", line 512, in dispatch
    response = handler(request, *args, **kwargs)
               ^^^^^^^^^^^^^^^^^^^^^^^^^^^^^^^^^
  File "/usr/local/lib/python3.11/site-packages/rest_framework/generics.py", line 203, in get
    return self.list(request, *args, **kwargs)
           ^^^^^^^^^^^^^^^^^^^^^^^^^^^^^^^^^^^
  File "/usr/local/lib/python3.11/site-packages/rest_framework/mixins.py", line 40, in list
    page = self.paginate_queryset(queryset)
           ^^^^^^^^^^^^^^^^^^^^^^^^^^^^^^^^
  File "/usr/local/lib/python3.11/site-packages/rest_framework/generics.py", line 175, in paginate_queryset
    return self.paginator.paginate_queryset(queryset, self.request, view=self)
           ^^^^^^^^^^^^^^^^^^^^^^^^^^^^^^^^^^^^^^^^^^^^^^^^^^^^^^^^^^^^^^^^^^^
  File "/usr/local/lib/python3.11/site-packages/rest_framework/pagination.py", line 211, in paginate_queryset
    self.page = paginator.page(page_number)
                ^^^^^^^^^^^^^^^^^^^^^^^^^^^
  File "/usr/local/lib/python3.11/site-packages/django/core/paginator.py", line 89, in page
    number = self.validate_number(number)
             ^^^^^^^^^^^^^^^^^^^^^^^^^^^^
  File "/usr/local/lib/python3.11/site-packages/django/core/paginator.py", line 70, in validate_number
    if number > self.num_pages:
                ^^^^^^^^^^^^^^
  File "/usr/local/lib/python3.11/site-packages/django/utils/functional.py", line 47, in __get__
    res = instance.__dict__[self.name] = self.func(instance)
                                         ^^^^^^^^^^^^^^^^^^^
  File "/usr/local/lib/python3.11/site-packages/django/core/paginator.py", line 116, in num_pages
    if self.count == 0 and not self.allow_empty_first_page:
       ^^^^^^^^^^
  File "/usr/local/lib/python3.11/site-packages/django/utils/functional.py", line 47, in __get__
    res = instance.__dict__[self.name] = self.func(instance)
                                         ^^^^^^^^^^^^^^^^^^^
  File "/usr/local/lib/python3.11/site-packages/django/core/paginator.py", line 110, in count
    return c()
           ^^^
  File "/usr/local/lib/python3.11/site-packages/django/db/models/query.py", line 604, in count
    return self.query.get_count(using=self.db)
           ^^^^^^^^^^^^^^^^^^^^^^^^^^^^^^^^^^^
  File "/usr/local/lib/python3.11/site-packages/django/db/models/sql/query.py", line 644, in get_count
    return obj.get_aggregation(using, {"__count": Count("*")})["__count"]
           ^^^^^^^^^^^^^^^^^^^^^^^^^^^^^^^^^^^^^^^^^^^^^^^^^^^
  File "/usr/local/lib/python3.11/site-packages/django/db/models/sql/query.py", line 626, in get_aggregation
    result = compiler.execute_sql(SINGLE)
             ^^^^^^^^^^^^^^^^^^^^^^^^^^^^
  File "/usr/local/lib/python3.11/site-packages/django/db/models/sql/compiler.py", line 1623, in execute_sql
    cursor.execute(sql, params)
  File "/usr/local/lib/python3.11/site-packages/django/db/backends/utils.py", line 122, in execute
    return super().execute(sql, params)
           ^^^^^^^^^^^^^^^^^^^^^^^^^^^^
  File "/usr/local/lib/python3.11/site-packages/django/db/backends/utils.py", line 79, in execute
    return self._execute_with_wrappers(
           ^^^^^^^^^^^^^^^^^^^^^^^^^^^^
  File "/usr/local/lib/python3.11/site-packages/django/db/backends/utils.py", line 92, in _execute_with_wrappers
    return executor(sql, params, many, context)
           ^^^^^^^^^^^^^^^^^^^^^^^^^^^^^^^^^^^^
  File "/usr/local/lib/python3.11/site-packages/django/db/backends/utils.py", line 100, in _execute
    with self.db.wrap_database_errors:
  File "/usr/local/lib/python3.11/site-packages/django/db/utils.py", line 91, in __exit__
    raise dj_exc_value.with_traceback(traceback) from exc_value
  File "/usr/local/lib/python3.11/site-packages/django/db/backends/utils.py", line 105, in _execute
    return self.cursor.execute(sql, params)
           ^^^^^^^^^^^^^^^^^^^^^^^^^^^^^^^^
django.db.utils.ProgrammingError: relation "job_applications_job_application" does not exist
LINE 1: SELECT COUNT(*) AS "__count" FROM "job_applications_job_appl...
                                          ^

2025-10-01 16:33:45,894 [ERROR] django.request: Internal Server Error: /api/applications-engine/applications/job-requisitions/PRO-0003/applications/
Traceback (most recent call last):
  File "/usr/local/lib/python3.11/site-packages/django/db/backends/utils.py", line 105, in _execute
    return self.cursor.execute(sql, params)
           ^^^^^^^^^^^^^^^^^^^^^^^^^^^^^^^^
psycopg2.errors.UndefinedTable: relation "job_applications_job_application" does not exist
LINE 1: SELECT COUNT(*) AS "__count" FROM "job_applications_job_appl...
                                          ^


The above exception was the direct cause of the following exception:

Traceback (most recent call last):
  File "/usr/local/lib/python3.11/site-packages/django/core/handlers/exception.py", line 55, in inner
    response = get_response(request)
               ^^^^^^^^^^^^^^^^^^^^^
  File "/usr/local/lib/python3.11/site-packages/django/core/handlers/base.py", line 197, in _get_response
    response = wrapped_callback(request, *callback_args, **callback_kwargs)
               ^^^^^^^^^^^^^^^^^^^^^^^^^^^^^^^^^^^^^^^^^^^^^^^^^^^^^^^^^^^^
  File "/usr/local/lib/python3.11/site-packages/django/views/decorators/csrf.py", line 65, in _view_wrapper
    return view_func(request, *args, **kwargs)
           ^^^^^^^^^^^^^^^^^^^^^^^^^^^^^^^^^^^
  File "/usr/local/lib/python3.11/site-packages/django/views/generic/base.py", line 105, in view
    return self.dispatch(request, *args, **kwargs)
           ^^^^^^^^^^^^^^^^^^^^^^^^^^^^^^^^^^^^^^^
  File "/usr/local/lib/python3.11/site-packages/rest_framework/views.py", line 515, in dispatch
    response = self.handle_exception(exc)
               ^^^^^^^^^^^^^^^^^^^^^^^^^^
  File "/usr/local/lib/python3.11/site-packages/rest_framework/views.py", line 475, in handle_exception
    self.raise_uncaught_exception(exc)
  File "/usr/local/lib/python3.11/site-packages/rest_framework/views.py", line 486, in raise_uncaught_exception
    raise exc
  File "/usr/local/lib/python3.11/site-packages/rest_framework/views.py", line 512, in dispatch
    response = handler(request, *args, **kwargs)
               ^^^^^^^^^^^^^^^^^^^^^^^^^^^^^^^^^
  File "/usr/local/lib/python3.11/site-packages/rest_framework/generics.py", line 203, in get
    return self.list(request, *args, **kwargs)
           ^^^^^^^^^^^^^^^^^^^^^^^^^^^^^^^^^^^
  File "/usr/local/lib/python3.11/site-packages/rest_framework/mixins.py", line 40, in list
    page = self.paginate_queryset(queryset)
           ^^^^^^^^^^^^^^^^^^^^^^^^^^^^^^^^
  File "/usr/local/lib/python3.11/site-packages/rest_framework/generics.py", line 175, in paginate_queryset
    return self.paginator.paginate_queryset(queryset, self.request, view=self)
           ^^^^^^^^^^^^^^^^^^^^^^^^^^^^^^^^^^^^^^^^^^^^^^^^^^^^^^^^^^^^^^^^^^^
  File "/usr/local/lib/python3.11/site-packages/rest_framework/pagination.py", line 211, in paginate_queryset
    self.page = paginator.page(page_number)
                ^^^^^^^^^^^^^^^^^^^^^^^^^^^
  File "/usr/local/lib/python3.11/site-packages/django/core/paginator.py", line 89, in page
    number = self.validate_number(number)
             ^^^^^^^^^^^^^^^^^^^^^^^^^^^^
  File "/usr/local/lib/python3.11/site-packages/django/core/paginator.py", line 70, in validate_number
    if number > self.num_pages:
                ^^^^^^^^^^^^^^
  File "/usr/local/lib/python3.11/site-packages/django/utils/functional.py", line 47, in __get__
    res = instance.__dict__[self.name] = self.func(instance)
                                         ^^^^^^^^^^^^^^^^^^^
  File "/usr/local/lib/python3.11/site-packages/django/core/paginator.py", line 116, in num_pages
    if self.count == 0 and not self.allow_empty_first_page:
       ^^^^^^^^^^
  File "/usr/local/lib/python3.11/site-packages/django/utils/functional.py", line 47, in __get__
    res = instance.__dict__[self.name] = self.func(instance)
                                         ^^^^^^^^^^^^^^^^^^^
  File "/usr/local/lib/python3.11/site-packages/django/core/paginator.py", line 110, in count
    return c()
           ^^^
  File "/usr/local/lib/python3.11/site-packages/django/db/models/query.py", line 604, in count
    return self.query.get_count(using=self.db)
           ^^^^^^^^^^^^^^^^^^^^^^^^^^^^^^^^^^^
  File "/usr/local/lib/python3.11/site-packages/django/db/models/sql/query.py", line 644, in get_count
    return obj.get_aggregation(using, {"__count": Count("*")})["__count"]
           ^^^^^^^^^^^^^^^^^^^^^^^^^^^^^^^^^^^^^^^^^^^^^^^^^^^
  File "/usr/local/lib/python3.11/site-packages/django/db/models/sql/query.py", line 626, in get_aggregation
    result = compiler.execute_sql(SINGLE)
             ^^^^^^^^^^^^^^^^^^^^^^^^^^^^
  File "/usr/local/lib/python3.11/site-packages/django/db/models/sql/compiler.py", line 1623, in execute_sql
    cursor.execute(sql, params)
  File "/usr/local/lib/python3.11/site-packages/django/db/backends/utils.py", line 122, in execute
    return super().execute(sql, params)
           ^^^^^^^^^^^^^^^^^^^^^^^^^^^^
  File "/usr/local/lib/python3.11/site-packages/django/db/backends/utils.py", line 79, in execute
    return self._execute_with_wrappers(
           ^^^^^^^^^^^^^^^^^^^^^^^^^^^^
  File "/usr/local/lib/python3.11/site-packages/django/db/backends/utils.py", line 92, in _execute_with_wrappers
    return executor(sql, params, many, context)
           ^^^^^^^^^^^^^^^^^^^^^^^^^^^^^^^^^^^^
  File "/usr/local/lib/python3.11/site-packages/django/db/backends/utils.py", line 100, in _execute
    with self.db.wrap_database_errors:
  File "/usr/local/lib/python3.11/site-packages/django/db/utils.py", line 91, in __exit__
    raise dj_exc_value.with_traceback(traceback) from exc_value
  File "/usr/local/lib/python3.11/site-packages/django/db/backends/utils.py", line 105, in _execute
    return self.cursor.execute(sql, params)
           ^^^^^^^^^^^^^^^^^^^^^^^^^^^^^^^^
django.db.utils.ProgrammingError: relation "job_applications_job_application" does not exist
LINE 1: SELECT COUNT(*) AS "__count" FROM "job_applications_job_appl...
                                          ^

2025-10-01 16:33:48,836 [INFO] job_applications: Entering MicroserviceRS256JWTMiddleware
2025-10-01 16:33:48,838 [INFO] job_applications: Fetching public key from: http://auth-service:8001/api/public-key/1f530d5313654d8781aaab5ea0de2065/?tenant_id=3
2025-10-01 16:33:48,840 [DEBUG] urllib3.connectionpool: Starting new HTTP connection (1): auth-service:8001
2025-10-01 16:33:48,860 [DEBUG] urllib3.connectionpool: http://auth-service:8001 "GET /api/public-key/1f530d5313654d8781aaab5ea0de2065/?tenant_id=3 HTTP/1.1" 200 477
2025-10-01 16:33:48,862 [DEBUG] urllib3.connectionpool: Starting new HTTP connection (1): auth-service:8001
2025-10-01 16:33:48,885 [DEBUG] urllib3.connectionpool: http://auth-service:8001 "GET /api/tenant/tenants/09145372-eb5d-40ff-9d93-ca49425a16e6/ HTTP/1.1" 200 428
2025-10-01 16:33:48,887 [INFO] job_applications: Set schema to: proliance
2025-10-01 16:33:48,904 [INFO] job_applications: Entering MicroserviceRS256JWTMiddleware
2025-10-01 16:33:48,906 [INFO] job_applications: Fetching public key from: http://auth-service:8001/api/public-key/1f530d5313654d8781aaab5ea0de2065/?tenant_id=3
2025-10-01 16:33:48,907 [DEBUG] urllib3.connectionpool: Starting new HTTP connection (1): auth-service:8001
2025-10-01 16:33:48,927 [DEBUG] urllib3.connectionpool: http://auth-service:8001 "GET /api/public-key/1f530d5313654d8781aaab5ea0de2065/?tenant_id=3 HTTP/1.1" 200 477
2025-10-01 16:33:48,929 [DEBUG] urllib3.connectionpool: Starting new HTTP connection (1): auth-service:8001
2025-10-01 16:33:48,951 [DEBUG] urllib3.connectionpool: http://auth-service:8001 "GET /api/tenant/tenants/09145372-eb5d-40ff-9d93-ca49425a16e6/ HTTP/1.1" 200 428
2025-10-01 16:33:48,953 [INFO] job_applications: Set schema to: proliance
2025-10-01 16:33:48,999 [ERROR] django.request: Internal Server Error: /api/applications-engine/applications/job-requisitions/PRO-0003/applications/
Traceback (most recent call last):
  File "/usr/local/lib/python3.11/site-packages/django/db/backends/utils.py", line 105, in _execute
    return self.cursor.execute(sql, params)
           ^^^^^^^^^^^^^^^^^^^^^^^^^^^^^^^^
psycopg2.errors.UndefinedTable: relation "job_applications_job_application" does not exist
LINE 1: SELECT COUNT(*) AS "__count" FROM "job_applications_job_appl...
                                          ^


The above exception was the direct cause of the following exception:

Traceback (most recent call last):
  File "/usr/local/lib/python3.11/site-packages/django/core/handlers/exception.py", line 55, in inner
    response = get_response(request)
               ^^^^^^^^^^^^^^^^^^^^^
  File "/usr/local/lib/python3.11/site-packages/django/core/handlers/base.py", line 197, in _get_response
    response = wrapped_callback(request, *callback_args, **callback_kwargs)
               ^^^^^^^^^^^^^^^^^^^^^^^^^^^^^^^^^^^^^^^^^^^^^^^^^^^^^^^^^^^^
  File "/usr/local/lib/python3.11/site-packages/django/views/decorators/csrf.py", line 65, in _view_wrapper
    return view_func(request, *args, **kwargs)
           ^^^^^^^^^^^^^^^^^^^^^^^^^^^^^^^^^^^
  File "/usr/local/lib/python3.11/site-packages/django/views/generic/base.py", line 105, in view
    return self.dispatch(request, *args, **kwargs)
           ^^^^^^^^^^^^^^^^^^^^^^^^^^^^^^^^^^^^^^^
  File "/usr/local/lib/python3.11/site-packages/rest_framework/views.py", line 515, in dispatch
    response = self.handle_exception(exc)
               ^^^^^^^^^^^^^^^^^^^^^^^^^^
  File "/usr/local/lib/python3.11/site-packages/rest_framework/views.py", line 475, in handle_exception
    self.raise_uncaught_exception(exc)
  File "/usr/local/lib/python3.11/site-packages/rest_framework/views.py", line 486, in raise_uncaught_exception
    raise exc
  File "/usr/local/lib/python3.11/site-packages/rest_framework/views.py", line 512, in dispatch
    response = handler(request, *args, **kwargs)
               ^^^^^^^^^^^^^^^^^^^^^^^^^^^^^^^^^
  File "/usr/local/lib/python3.11/site-packages/rest_framework/generics.py", line 203, in get
    return self.list(request, *args, **kwargs)
           ^^^^^^^^^^^^^^^^^^^^^^^^^^^^^^^^^^^
  File "/usr/local/lib/python3.11/site-packages/rest_framework/mixins.py", line 40, in list
    page = self.paginate_queryset(queryset)
           ^^^^^^^^^^^^^^^^^^^^^^^^^^^^^^^^
  File "/usr/local/lib/python3.11/site-packages/rest_framework/generics.py", line 175, in paginate_queryset
    return self.paginator.paginate_queryset(queryset, self.request, view=self)
           ^^^^^^^^^^^^^^^^^^^^^^^^^^^^^^^^^^^^^^^^^^^^^^^^^^^^^^^^^^^^^^^^^^^
  File "/usr/local/lib/python3.11/site-packages/rest_framework/pagination.py", line 211, in paginate_queryset
    self.page = paginator.page(page_number)
                ^^^^^^^^^^^^^^^^^^^^^^^^^^^
  File "/usr/local/lib/python3.11/site-packages/django/core/paginator.py", line 89, in page
    number = self.validate_number(number)
             ^^^^^^^^^^^^^^^^^^^^^^^^^^^^
  File "/usr/local/lib/python3.11/site-packages/django/core/paginator.py", line 70, in validate_number
    if number > self.num_pages:
                ^^^^^^^^^^^^^^
  File "/usr/local/lib/python3.11/site-packages/django/utils/functional.py", line 47, in __get__
    res = instance.__dict__[self.name] = self.func(instance)
                                         ^^^^^^^^^^^^^^^^^^^
  File "/usr/local/lib/python3.11/site-packages/django/core/paginator.py", line 116, in num_pages
    if self.count == 0 and not self.allow_empty_first_page:
       ^^^^^^^^^^
  File "/usr/local/lib/python3.11/site-packages/django/utils/functional.py", line 47, in __get__
    res = instance.__dict__[self.name] = self.func(instance)
                                         ^^^^^^^^^^^^^^^^^^^
  File "/usr/local/lib/python3.11/site-packages/django/core/paginator.py", line 110, in count
    return c()
           ^^^
  File "/usr/local/lib/python3.11/site-packages/django/db/models/query.py", line 604, in count
    return self.query.get_count(using=self.db)
           ^^^^^^^^^^^^^^^^^^^^^^^^^^^^^^^^^^^
  File "/usr/local/lib/python3.11/site-packages/django/db/models/sql/query.py", line 644, in get_count
    return obj.get_aggregation(using, {"__count": Count("*")})["__count"]
           ^^^^^^^^^^^^^^^^^^^^^^^^^^^^^^^^^^^^^^^^^^^^^^^^^^^
  File "/usr/local/lib/python3.11/site-packages/django/db/models/sql/query.py", line 626, in get_aggregation
    result = compiler.execute_sql(SINGLE)
             ^^^^^^^^^^^^^^^^^^^^^^^^^^^^
  File "/usr/local/lib/python3.11/site-packages/django/db/models/sql/compiler.py", line 1623, in execute_sql
    cursor.execute(sql, params)
  File "/usr/local/lib/python3.11/site-packages/django/db/backends/utils.py", line 122, in execute
    return super().execute(sql, params)
           ^^^^^^^^^^^^^^^^^^^^^^^^^^^^
  File "/usr/local/lib/python3.11/site-packages/django/db/backends/utils.py", line 79, in execute
    return self._execute_with_wrappers(
           ^^^^^^^^^^^^^^^^^^^^^^^^^^^^
  File "/usr/local/lib/python3.11/site-packages/django/db/backends/utils.py", line 92, in _execute_with_wrappers
    return executor(sql, params, many, context)
           ^^^^^^^^^^^^^^^^^^^^^^^^^^^^^^^^^^^^
  File "/usr/local/lib/python3.11/site-packages/django/db/backends/utils.py", line 100, in _execute
    with self.db.wrap_database_errors:
  File "/usr/local/lib/python3.11/site-packages/django/db/utils.py", line 91, in __exit__
    raise dj_exc_value.with_traceback(traceback) from exc_value
  File "/usr/local/lib/python3.11/site-packages/django/db/backends/utils.py", line 105, in _execute
    return self.cursor.execute(sql, params)
           ^^^^^^^^^^^^^^^^^^^^^^^^^^^^^^^^
django.db.utils.ProgrammingError: relation "job_applications_job_application" does not exist
LINE 1: SELECT COUNT(*) AS "__count" FROM "job_applications_job_appl...
                                          ^

2025-10-01 16:33:48,999 [ERROR] django.request: Internal Server Error: /api/applications-engine/applications/job-requisitions/PRO-0003/applications/
Traceback (most recent call last):
  File "/usr/local/lib/python3.11/site-packages/django/db/backends/utils.py", line 105, in _execute
    return self.cursor.execute(sql, params)
           ^^^^^^^^^^^^^^^^^^^^^^^^^^^^^^^^
psycopg2.errors.UndefinedTable: relation "job_applications_job_application" does not exist
LINE 1: SELECT COUNT(*) AS "__count" FROM "job_applications_job_appl...
                                          ^


The above exception was the direct cause of the following exception:

Traceback (most recent call last):
  File "/usr/local/lib/python3.11/site-packages/django/core/handlers/exception.py", line 55, in inner
    response = get_response(request)
               ^^^^^^^^^^^^^^^^^^^^^
  File "/usr/local/lib/python3.11/site-packages/django/core/handlers/base.py", line 197, in _get_response
    response = wrapped_callback(request, *callback_args, **callback_kwargs)
               ^^^^^^^^^^^^^^^^^^^^^^^^^^^^^^^^^^^^^^^^^^^^^^^^^^^^^^^^^^^^
  File "/usr/local/lib/python3.11/site-packages/django/views/decorators/csrf.py", line 65, in _view_wrapper
    return view_func(request, *args, **kwargs)
           ^^^^^^^^^^^^^^^^^^^^^^^^^^^^^^^^^^^
  File "/usr/local/lib/python3.11/site-packages/django/views/generic/base.py", line 105, in view
    return self.dispatch(request, *args, **kwargs)
           ^^^^^^^^^^^^^^^^^^^^^^^^^^^^^^^^^^^^^^^
  File "/usr/local/lib/python3.11/site-packages/rest_framework/views.py", line 515, in dispatch
    response = self.handle_exception(exc)
               ^^^^^^^^^^^^^^^^^^^^^^^^^^
  File "/usr/local/lib/python3.11/site-packages/rest_framework/views.py", line 475, in handle_exception
    self.raise_uncaught_exception(exc)
  File "/usr/local/lib/python3.11/site-packages/rest_framework/views.py", line 486, in raise_uncaught_exception
    raise exc
  File "/usr/local/lib/python3.11/site-packages/rest_framework/views.py", line 512, in dispatch
    response = handler(request, *args, **kwargs)
               ^^^^^^^^^^^^^^^^^^^^^^^^^^^^^^^^^
  File "/usr/local/lib/python3.11/site-packages/rest_framework/generics.py", line 203, in get
    return self.list(request, *args, **kwargs)
           ^^^^^^^^^^^^^^^^^^^^^^^^^^^^^^^^^^^
  File "/usr/local/lib/python3.11/site-packages/rest_framework/mixins.py", line 40, in list
    page = self.paginate_queryset(queryset)
           ^^^^^^^^^^^^^^^^^^^^^^^^^^^^^^^^
  File "/usr/local/lib/python3.11/site-packages/rest_framework/generics.py", line 175, in paginate_queryset
    return self.paginator.paginate_queryset(queryset, self.request, view=self)
           ^^^^^^^^^^^^^^^^^^^^^^^^^^^^^^^^^^^^^^^^^^^^^^^^^^^^^^^^^^^^^^^^^^^
  File "/usr/local/lib/python3.11/site-packages/rest_framework/pagination.py", line 211, in paginate_queryset
    self.page = paginator.page(page_number)
                ^^^^^^^^^^^^^^^^^^^^^^^^^^^
  File "/usr/local/lib/python3.11/site-packages/django/core/paginator.py", line 89, in page
    number = self.validate_number(number)
             ^^^^^^^^^^^^^^^^^^^^^^^^^^^^
  File "/usr/local/lib/python3.11/site-packages/django/core/paginator.py", line 70, in validate_number
    if number > self.num_pages:
                ^^^^^^^^^^^^^^
  File "/usr/local/lib/python3.11/site-packages/django/utils/functional.py", line 47, in __get__
    res = instance.__dict__[self.name] = self.func(instance)
                                         ^^^^^^^^^^^^^^^^^^^
  File "/usr/local/lib/python3.11/site-packages/django/core/paginator.py", line 116, in num_pages
    if self.count == 0 and not self.allow_empty_first_page:
       ^^^^^^^^^^
  File "/usr/local/lib/python3.11/site-packages/django/utils/functional.py", line 47, in __get__
    res = instance.__dict__[self.name] = self.func(instance)
                                         ^^^^^^^^^^^^^^^^^^^
  File "/usr/local/lib/python3.11/site-packages/django/core/paginator.py", line 110, in count
    return c()
           ^^^
  File "/usr/local/lib/python3.11/site-packages/django/db/models/query.py", line 604, in count
    return self.query.get_count(using=self.db)
           ^^^^^^^^^^^^^^^^^^^^^^^^^^^^^^^^^^^
  File "/usr/local/lib/python3.11/site-packages/django/db/models/sql/query.py", line 644, in get_count
    return obj.get_aggregation(using, {"__count": Count("*")})["__count"]
           ^^^^^^^^^^^^^^^^^^^^^^^^^^^^^^^^^^^^^^^^^^^^^^^^^^^
  File "/usr/local/lib/python3.11/site-packages/django/db/models/sql/query.py", line 626, in get_aggregation
    result = compiler.execute_sql(SINGLE)
             ^^^^^^^^^^^^^^^^^^^^^^^^^^^^
  File "/usr/local/lib/python3.11/site-packages/django/db/models/sql/compiler.py", line 1623, in execute_sql
    cursor.execute(sql, params)
  File "/usr/local/lib/python3.11/site-packages/django/db/backends/utils.py", line 122, in execute
    return super().execute(sql, params)
           ^^^^^^^^^^^^^^^^^^^^^^^^^^^^
  File "/usr/local/lib/python3.11/site-packages/django/db/backends/utils.py", line 79, in execute
    return self._execute_with_wrappers(
           ^^^^^^^^^^^^^^^^^^^^^^^^^^^^
  File "/usr/local/lib/python3.11/site-packages/django/db/backends/utils.py", line 92, in _execute_with_wrappers
    return executor(sql, params, many, context)
           ^^^^^^^^^^^^^^^^^^^^^^^^^^^^^^^^^^^^
  File "/usr/local/lib/python3.11/site-packages/django/db/backends/utils.py", line 100, in _execute
    with self.db.wrap_database_errors:
  File "/usr/local/lib/python3.11/site-packages/django/db/utils.py", line 91, in __exit__
    raise dj_exc_value.with_traceback(traceback) from exc_value
  File "/usr/local/lib/python3.11/site-packages/django/db/backends/utils.py", line 105, in _execute
    return self.cursor.execute(sql, params)
           ^^^^^^^^^^^^^^^^^^^^^^^^^^^^^^^^
django.db.utils.ProgrammingError: relation "job_applications_job_application" does not exist
LINE 1: SELECT COUNT(*) AS "__count" FROM "job_applications_job_appl...
                                          ^

2025-10-01 16:34:38,673 [INFO] job_applications.settings: Logging configuration applied successfully
2025-10-01 16:34:38,675 [DEBUG] environ.environ: get 'CELERY_BROKER_URL' casted as 'None' with default 'redis://job_app_redis:6379/0'
2025-10-01 16:34:38,677 [DEBUG] environ.environ: get 'CELERY_RESULT_BACKEND' casted as 'None' with default 'redis://job_app_redis:6379/0'
2025-10-01 16:34:39,463 [INFO] job_applications.settings: Logging configuration applied successfully
2025-10-01 16:34:39,463 [INFO] job_applications.settings: Logging configuration applied successfully
2025-10-01 16:34:39,465 [DEBUG] environ.environ: get 'CELERY_BROKER_URL' casted as 'None' with default 'redis://job_app_redis:6379/0'
2025-10-01 16:34:39,465 [DEBUG] environ.environ: get 'CELERY_BROKER_URL' casted as 'None' with default 'redis://job_app_redis:6379/0'
2025-10-01 16:34:39,466 [DEBUG] environ.environ: get 'CELERY_RESULT_BACKEND' casted as 'None' with default 'redis://job_app_redis:6379/0'
2025-10-01 16:34:39,466 [DEBUG] environ.environ: get 'CELERY_RESULT_BACKEND' casted as 'None' with default 'redis://job_app_redis:6379/0'
2025-10-01 16:34:58,837 [DEBUG] celery.utils.functional: 
def chord(self, header, body, partial_args=0, interval=1, countdown=2, max_retries=3, eager=4, **kwargs):
    return 1

2025-10-01 16:34:58,840 [DEBUG] celery.utils.functional: 
def process_resume_chunk(self, job_requisition_id, tenant_id, document_type, applications_chunk, chunk_index, total_chunks, role=0, branch=1, authorization_header=2, job_requirements=3):
    return 1

2025-10-01 16:34:58,842 [DEBUG] celery.utils.functional: 
def chunks(task, it, n):
    return 1

2025-10-01 16:34:58,844 [DEBUG] celery.utils.functional: 
def aggregate_screening_results(self, chunk_results, job_requisition_id, tenant_id, num_candidates, document_type, authorization_header=0):
    return 1

2025-10-01 16:34:58,846 [DEBUG] celery.utils.functional: 
def unlock_chord(self, group_id, callback, interval=0, max_retries=1, result=2, Result=3, GroupResult=4, result_from_tuple=5, **kwargs):
    return 1

2025-10-01 16:34:58,848 [DEBUG] celery.utils.functional: 
def group(self, tasks, result, group_id, partial_args, add_to_parent=0):
    return 1

2025-10-01 16:34:58,850 [DEBUG] celery.utils.functional: 
def xmap(task, it):
    return 1

2025-10-01 16:34:58,852 [DEBUG] celery.utils.functional: 
def backend_cleanup():
    return 1

2025-10-01 16:34:58,854 [DEBUG] celery.utils.functional: 
def screen_resumes_task(job_requisition_id, document_type, num_candidates, applications_data, job_requisition):
    return 1

2025-10-01 16:34:58,856 [DEBUG] celery.utils.functional: 
def auto_screen_all_applications():
    return 1

2025-10-01 16:34:58,858 [DEBUG] celery.utils.functional: 
def chain(*args, **kwargs):
    return 1

2025-10-01 16:34:58,858 [DEBUG] celery.utils.functional: 
def chord(self, header, body, partial_args=0, interval=1, countdown=2, max_retries=3, eager=4, **kwargs):
    return 1

2025-10-01 16:34:58,859 [DEBUG] celery.utils.functional: 
def xstarmap(task, it):
    return 1

2025-10-01 16:34:58,860 [DEBUG] celery.utils.functional: 
def process_resume_chunk(self, job_requisition_id, tenant_id, document_type, applications_chunk, chunk_index, total_chunks, role=0, branch=1, authorization_header=2, job_requirements=3):
    return 1

2025-10-01 16:34:58,861 [DEBUG] celery.utils.functional: 
def accumulate(self, *args, **kwargs):
    return 1

2025-10-01 16:34:58,862 [DEBUG] celery.utils.functional: 
def chunks(task, it, n):
    return 1

2025-10-01 16:34:58,863 [DEBUG] celery.utils.functional: 
def send_notification_task(self, applicant_data, tenant_id, event_type, employment_gaps=0):
    return 1

2025-10-01 16:34:58,865 [DEBUG] celery.utils.functional: 
def process_large_resume_batch(self, job_requisition_id, tenant_id, document_type, applications_data, num_candidates, role=0, branch=1, authorization_header=2):
    return 1

2025-10-01 16:34:58,865 [DEBUG] celery.utils.functional: 
def unlock_chord(self, group_id, callback, interval=0, max_retries=1, result=2, Result=3, GroupResult=4, result_from_tuple=5, **kwargs):
    return 1

2025-10-01 16:34:58,867 [DEBUG] celery.utils.functional: 
def group(self, tasks, result, group_id, partial_args, add_to_parent=0):
    return 1

2025-10-01 16:34:58,869 [DEBUG] celery.utils.functional: 
def screen_resumes_task(job_requisition_id, document_type, num_candidates, applications_data, job_requisition):
    return 1

2025-10-01 16:34:58,871 [DEBUG] celery.utils.functional: 
def xmap(task, it):
    return 1

2025-10-01 16:34:58,872 [DEBUG] celery.utils.functional: 
def auto_screen_all_applications():
    return 1

2025-10-01 16:34:58,874 [DEBUG] celery.utils.functional: 
def backend_cleanup():
    return 1

2025-10-01 16:34:58,876 [DEBUG] celery.utils.functional: 
def chain(*args, **kwargs):
    return 1

2025-10-01 16:34:58,878 [DEBUG] celery.utils.functional: 
def xstarmap(task, it):
    return 1

2025-10-01 16:34:58,880 [DEBUG] celery.utils.functional: 
def process_large_resume_batch(self, job_requisition_id, tenant_id, document_type, applications_data, num_candidates, role=0, branch=1, authorization_header=2):
    return 1

2025-10-01 16:34:58,881 [DEBUG] celery.utils.functional: 
def accumulate(self, *args, **kwargs):
    return 1

2025-10-01 16:34:58,883 [DEBUG] celery.utils.functional: 
def send_notification_task(self, applicant_data, tenant_id, event_type, employment_gaps=0):
    return 1

2025-10-01 16:34:58,885 [DEBUG] celery.utils.functional: 
def aggregate_screening_results(self, chunk_results, job_requisition_id, tenant_id, num_candidates, document_type, authorization_header=0):
    return 1

2025-10-01 16:35:16,867 [INFO] job_applications: Entering MicroserviceRS256JWTMiddleware
2025-10-01 16:35:16,868 [INFO] job_applications: Fetching public key from: http://auth-service:8001/api/public-key/1f530d5313654d8781aaab5ea0de2065/?tenant_id=3
2025-10-01 16:35:16,873 [DEBUG] urllib3.connectionpool: Starting new HTTP connection (1): auth-service:8001
2025-10-01 16:35:16,913 [DEBUG] urllib3.connectionpool: http://auth-service:8001 "GET /api/public-key/1f530d5313654d8781aaab5ea0de2065/?tenant_id=3 HTTP/1.1" 200 477
2025-10-01 16:35:16,918 [DEBUG] urllib3.connectionpool: Starting new HTTP connection (1): auth-service:8001
2025-10-01 16:35:16,944 [DEBUG] urllib3.connectionpool: http://auth-service:8001 "GET /api/tenant/tenants/09145372-eb5d-40ff-9d93-ca49425a16e6/ HTTP/1.1" 200 428
2025-10-01 16:35:16,945 [INFO] job_applications: Set schema to: proliance
2025-10-01 16:35:31,069 [INFO] job_applications: Entering MicroserviceRS256JWTMiddleware
2025-10-01 16:35:31,072 [INFO] job_applications: Fetching public key from: http://auth-service:8001/api/public-key/1f530d5313654d8781aaab5ea0de2065/?tenant_id=3
2025-10-01 16:35:31,075 [DEBUG] urllib3.connectionpool: Starting new HTTP connection (1): auth-service:8001
2025-10-01 16:35:31,105 [DEBUG] urllib3.connectionpool: http://auth-service:8001 "GET /api/public-key/1f530d5313654d8781aaab5ea0de2065/?tenant_id=3 HTTP/1.1" 200 477
2025-10-01 16:35:31,108 [DEBUG] urllib3.connectionpool: Starting new HTTP connection (1): auth-service:8001
2025-10-01 16:35:31,140 [DEBUG] urllib3.connectionpool: http://auth-service:8001 "GET /api/tenant/tenants/09145372-eb5d-40ff-9d93-ca49425a16e6/ HTTP/1.1" 200 428
2025-10-01 16:35:31,143 [INFO] job_applications: Set schema to: proliance
2025-10-01 16:35:31,247 [ERROR] django.request: Internal Server Error: /api/applications-engine/applications/job-requisitions/PRO-0003/applications/
Traceback (most recent call last):
  File "/usr/local/lib/python3.11/site-packages/django/db/backends/utils.py", line 105, in _execute
    return self.cursor.execute(sql, params)
           ^^^^^^^^^^^^^^^^^^^^^^^^^^^^^^^^
psycopg2.errors.UndefinedTable: relation "job_applications_job_application" does not exist
LINE 1: SELECT COUNT(*) AS "__count" FROM "job_applications_job_appl...
                                          ^


The above exception was the direct cause of the following exception:

Traceback (most recent call last):
  File "/usr/local/lib/python3.11/site-packages/django/core/handlers/exception.py", line 55, in inner
    response = get_response(request)
               ^^^^^^^^^^^^^^^^^^^^^
  File "/usr/local/lib/python3.11/site-packages/django/core/handlers/base.py", line 197, in _get_response
    response = wrapped_callback(request, *callback_args, **callback_kwargs)
               ^^^^^^^^^^^^^^^^^^^^^^^^^^^^^^^^^^^^^^^^^^^^^^^^^^^^^^^^^^^^
  File "/usr/local/lib/python3.11/site-packages/django/views/decorators/csrf.py", line 65, in _view_wrapper
    return view_func(request, *args, **kwargs)
           ^^^^^^^^^^^^^^^^^^^^^^^^^^^^^^^^^^^
  File "/usr/local/lib/python3.11/site-packages/django/views/generic/base.py", line 105, in view
    return self.dispatch(request, *args, **kwargs)
           ^^^^^^^^^^^^^^^^^^^^^^^^^^^^^^^^^^^^^^^
  File "/usr/local/lib/python3.11/site-packages/rest_framework/views.py", line 515, in dispatch
    response = self.handle_exception(exc)
               ^^^^^^^^^^^^^^^^^^^^^^^^^^
  File "/usr/local/lib/python3.11/site-packages/rest_framework/views.py", line 475, in handle_exception
    self.raise_uncaught_exception(exc)
  File "/usr/local/lib/python3.11/site-packages/rest_framework/views.py", line 486, in raise_uncaught_exception
    raise exc
  File "/usr/local/lib/python3.11/site-packages/rest_framework/views.py", line 512, in dispatch
    response = handler(request, *args, **kwargs)
               ^^^^^^^^^^^^^^^^^^^^^^^^^^^^^^^^^
  File "/usr/local/lib/python3.11/site-packages/rest_framework/generics.py", line 203, in get
    return self.list(request, *args, **kwargs)
           ^^^^^^^^^^^^^^^^^^^^^^^^^^^^^^^^^^^
  File "/usr/local/lib/python3.11/site-packages/rest_framework/mixins.py", line 40, in list
    page = self.paginate_queryset(queryset)
           ^^^^^^^^^^^^^^^^^^^^^^^^^^^^^^^^
  File "/usr/local/lib/python3.11/site-packages/rest_framework/generics.py", line 175, in paginate_queryset
    return self.paginator.paginate_queryset(queryset, self.request, view=self)
           ^^^^^^^^^^^^^^^^^^^^^^^^^^^^^^^^^^^^^^^^^^^^^^^^^^^^^^^^^^^^^^^^^^^
  File "/usr/local/lib/python3.11/site-packages/rest_framework/pagination.py", line 211, in paginate_queryset
    self.page = paginator.page(page_number)
                ^^^^^^^^^^^^^^^^^^^^^^^^^^^
  File "/usr/local/lib/python3.11/site-packages/django/core/paginator.py", line 89, in page
    number = self.validate_number(number)
             ^^^^^^^^^^^^^^^^^^^^^^^^^^^^
  File "/usr/local/lib/python3.11/site-packages/django/core/paginator.py", line 70, in validate_number
    if number > self.num_pages:
                ^^^^^^^^^^^^^^
  File "/usr/local/lib/python3.11/site-packages/django/utils/functional.py", line 47, in __get__
    res = instance.__dict__[self.name] = self.func(instance)
                                         ^^^^^^^^^^^^^^^^^^^
  File "/usr/local/lib/python3.11/site-packages/django/core/paginator.py", line 116, in num_pages
    if self.count == 0 and not self.allow_empty_first_page:
       ^^^^^^^^^^
  File "/usr/local/lib/python3.11/site-packages/django/utils/functional.py", line 47, in __get__
    res = instance.__dict__[self.name] = self.func(instance)
                                         ^^^^^^^^^^^^^^^^^^^
  File "/usr/local/lib/python3.11/site-packages/django/core/paginator.py", line 110, in count
    return c()
           ^^^
  File "/usr/local/lib/python3.11/site-packages/django/db/models/query.py", line 604, in count
    return self.query.get_count(using=self.db)
           ^^^^^^^^^^^^^^^^^^^^^^^^^^^^^^^^^^^
  File "/usr/local/lib/python3.11/site-packages/django/db/models/sql/query.py", line 644, in get_count
    return obj.get_aggregation(using, {"__count": Count("*")})["__count"]
           ^^^^^^^^^^^^^^^^^^^^^^^^^^^^^^^^^^^^^^^^^^^^^^^^^^^
  File "/usr/local/lib/python3.11/site-packages/django/db/models/sql/query.py", line 626, in get_aggregation
    result = compiler.execute_sql(SINGLE)
             ^^^^^^^^^^^^^^^^^^^^^^^^^^^^
  File "/usr/local/lib/python3.11/site-packages/django/db/models/sql/compiler.py", line 1623, in execute_sql
    cursor.execute(sql, params)
  File "/usr/local/lib/python3.11/site-packages/django/db/backends/utils.py", line 122, in execute
    return super().execute(sql, params)
           ^^^^^^^^^^^^^^^^^^^^^^^^^^^^
  File "/usr/local/lib/python3.11/site-packages/django/db/backends/utils.py", line 79, in execute
    return self._execute_with_wrappers(
           ^^^^^^^^^^^^^^^^^^^^^^^^^^^^
  File "/usr/local/lib/python3.11/site-packages/django/db/backends/utils.py", line 92, in _execute_with_wrappers
    return executor(sql, params, many, context)
           ^^^^^^^^^^^^^^^^^^^^^^^^^^^^^^^^^^^^
  File "/usr/local/lib/python3.11/site-packages/django/db/backends/utils.py", line 100, in _execute
    with self.db.wrap_database_errors:
  File "/usr/local/lib/python3.11/site-packages/django/db/utils.py", line 91, in __exit__
    raise dj_exc_value.with_traceback(traceback) from exc_value
  File "/usr/local/lib/python3.11/site-packages/django/db/backends/utils.py", line 105, in _execute
    return self.cursor.execute(sql, params)
           ^^^^^^^^^^^^^^^^^^^^^^^^^^^^^^^^
django.db.utils.ProgrammingError: relation "job_applications_job_application" does not exist
LINE 1: SELECT COUNT(*) AS "__count" FROM "job_applications_job_appl...
                                          ^

2025-10-01 16:35:31,247 [ERROR] django.request: Internal Server Error: /api/applications-engine/applications/job-requisitions/PRO-0003/applications/
Traceback (most recent call last):
  File "/usr/local/lib/python3.11/site-packages/django/db/backends/utils.py", line 105, in _execute
    return self.cursor.execute(sql, params)
           ^^^^^^^^^^^^^^^^^^^^^^^^^^^^^^^^
psycopg2.errors.UndefinedTable: relation "job_applications_job_application" does not exist
LINE 1: SELECT COUNT(*) AS "__count" FROM "job_applications_job_appl...
                                          ^


The above exception was the direct cause of the following exception:

Traceback (most recent call last):
  File "/usr/local/lib/python3.11/site-packages/django/core/handlers/exception.py", line 55, in inner
    response = get_response(request)
               ^^^^^^^^^^^^^^^^^^^^^
  File "/usr/local/lib/python3.11/site-packages/django/core/handlers/base.py", line 197, in _get_response
    response = wrapped_callback(request, *callback_args, **callback_kwargs)
               ^^^^^^^^^^^^^^^^^^^^^^^^^^^^^^^^^^^^^^^^^^^^^^^^^^^^^^^^^^^^
  File "/usr/local/lib/python3.11/site-packages/django/views/decorators/csrf.py", line 65, in _view_wrapper
    return view_func(request, *args, **kwargs)
           ^^^^^^^^^^^^^^^^^^^^^^^^^^^^^^^^^^^
  File "/usr/local/lib/python3.11/site-packages/django/views/generic/base.py", line 105, in view
    return self.dispatch(request, *args, **kwargs)
           ^^^^^^^^^^^^^^^^^^^^^^^^^^^^^^^^^^^^^^^
  File "/usr/local/lib/python3.11/site-packages/rest_framework/views.py", line 515, in dispatch
    response = self.handle_exception(exc)
               ^^^^^^^^^^^^^^^^^^^^^^^^^^
  File "/usr/local/lib/python3.11/site-packages/rest_framework/views.py", line 475, in handle_exception
    self.raise_uncaught_exception(exc)
  File "/usr/local/lib/python3.11/site-packages/rest_framework/views.py", line 486, in raise_uncaught_exception
    raise exc
  File "/usr/local/lib/python3.11/site-packages/rest_framework/views.py", line 512, in dispatch
    response = handler(request, *args, **kwargs)
               ^^^^^^^^^^^^^^^^^^^^^^^^^^^^^^^^^
  File "/usr/local/lib/python3.11/site-packages/rest_framework/generics.py", line 203, in get
    return self.list(request, *args, **kwargs)
           ^^^^^^^^^^^^^^^^^^^^^^^^^^^^^^^^^^^
  File "/usr/local/lib/python3.11/site-packages/rest_framework/mixins.py", line 40, in list
    page = self.paginate_queryset(queryset)
           ^^^^^^^^^^^^^^^^^^^^^^^^^^^^^^^^
  File "/usr/local/lib/python3.11/site-packages/rest_framework/generics.py", line 175, in paginate_queryset
    return self.paginator.paginate_queryset(queryset, self.request, view=self)
           ^^^^^^^^^^^^^^^^^^^^^^^^^^^^^^^^^^^^^^^^^^^^^^^^^^^^^^^^^^^^^^^^^^^
  File "/usr/local/lib/python3.11/site-packages/rest_framework/pagination.py", line 211, in paginate_queryset
    self.page = paginator.page(page_number)
                ^^^^^^^^^^^^^^^^^^^^^^^^^^^
  File "/usr/local/lib/python3.11/site-packages/django/core/paginator.py", line 89, in page
    number = self.validate_number(number)
             ^^^^^^^^^^^^^^^^^^^^^^^^^^^^
  File "/usr/local/lib/python3.11/site-packages/django/core/paginator.py", line 70, in validate_number
    if number > self.num_pages:
                ^^^^^^^^^^^^^^
  File "/usr/local/lib/python3.11/site-packages/django/utils/functional.py", line 47, in __get__
    res = instance.__dict__[self.name] = self.func(instance)
                                         ^^^^^^^^^^^^^^^^^^^
  File "/usr/local/lib/python3.11/site-packages/django/core/paginator.py", line 116, in num_pages
    if self.count == 0 and not self.allow_empty_first_page:
       ^^^^^^^^^^
  File "/usr/local/lib/python3.11/site-packages/django/utils/functional.py", line 47, in __get__
    res = instance.__dict__[self.name] = self.func(instance)
                                         ^^^^^^^^^^^^^^^^^^^
  File "/usr/local/lib/python3.11/site-packages/django/core/paginator.py", line 110, in count
    return c()
           ^^^
  File "/usr/local/lib/python3.11/site-packages/django/db/models/query.py", line 604, in count
    return self.query.get_count(using=self.db)
           ^^^^^^^^^^^^^^^^^^^^^^^^^^^^^^^^^^^
  File "/usr/local/lib/python3.11/site-packages/django/db/models/sql/query.py", line 644, in get_count
    return obj.get_aggregation(using, {"__count": Count("*")})["__count"]
           ^^^^^^^^^^^^^^^^^^^^^^^^^^^^^^^^^^^^^^^^^^^^^^^^^^^
  File "/usr/local/lib/python3.11/site-packages/django/db/models/sql/query.py", line 626, in get_aggregation
    result = compiler.execute_sql(SINGLE)
             ^^^^^^^^^^^^^^^^^^^^^^^^^^^^
  File "/usr/local/lib/python3.11/site-packages/django/db/models/sql/compiler.py", line 1623, in execute_sql
    cursor.execute(sql, params)
  File "/usr/local/lib/python3.11/site-packages/django/db/backends/utils.py", line 122, in execute
    return super().execute(sql, params)
           ^^^^^^^^^^^^^^^^^^^^^^^^^^^^
  File "/usr/local/lib/python3.11/site-packages/django/db/backends/utils.py", line 79, in execute
    return self._execute_with_wrappers(
           ^^^^^^^^^^^^^^^^^^^^^^^^^^^^
  File "/usr/local/lib/python3.11/site-packages/django/db/backends/utils.py", line 92, in _execute_with_wrappers
    return executor(sql, params, many, context)
           ^^^^^^^^^^^^^^^^^^^^^^^^^^^^^^^^^^^^
  File "/usr/local/lib/python3.11/site-packages/django/db/backends/utils.py", line 100, in _execute
    with self.db.wrap_database_errors:
  File "/usr/local/lib/python3.11/site-packages/django/db/utils.py", line 91, in __exit__
    raise dj_exc_value.with_traceback(traceback) from exc_value
  File "/usr/local/lib/python3.11/site-packages/django/db/backends/utils.py", line 105, in _execute
    return self.cursor.execute(sql, params)
           ^^^^^^^^^^^^^^^^^^^^^^^^^^^^^^^^
django.db.utils.ProgrammingError: relation "job_applications_job_application" does not exist
LINE 1: SELECT COUNT(*) AS "__count" FROM "job_applications_job_appl...
                                          ^

2025-10-01 16:35:39,153 [INFO] job_applications: Entering MicroserviceRS256JWTMiddleware
2025-10-01 16:35:39,155 [INFO] job_applications: Fetching public key from: http://auth-service:8001/api/public-key/1f530d5313654d8781aaab5ea0de2065/?tenant_id=3
2025-10-01 16:35:39,157 [DEBUG] urllib3.connectionpool: Starting new HTTP connection (1): auth-service:8001
2025-10-01 16:35:39,178 [DEBUG] urllib3.connectionpool: http://auth-service:8001 "GET /api/public-key/1f530d5313654d8781aaab5ea0de2065/?tenant_id=3 HTTP/1.1" 200 477
2025-10-01 16:35:39,181 [DEBUG] urllib3.connectionpool: Starting new HTTP connection (1): auth-service:8001
2025-10-01 16:35:39,203 [DEBUG] urllib3.connectionpool: http://auth-service:8001 "GET /api/tenant/tenants/09145372-eb5d-40ff-9d93-ca49425a16e6/ HTTP/1.1" 200 428
2025-10-01 16:35:39,205 [INFO] job_applications: Set schema to: proliance
2025-10-01 16:35:39,226 [INFO] job_applications: Entering MicroserviceRS256JWTMiddleware
2025-10-01 16:35:39,227 [INFO] job_applications: Fetching public key from: http://auth-service:8001/api/public-key/1f530d5313654d8781aaab5ea0de2065/?tenant_id=3
2025-10-01 16:35:39,229 [DEBUG] urllib3.connectionpool: Starting new HTTP connection (1): auth-service:8001
2025-10-01 16:35:39,248 [DEBUG] urllib3.connectionpool: http://auth-service:8001 "GET /api/public-key/1f530d5313654d8781aaab5ea0de2065/?tenant_id=3 HTTP/1.1" 200 477
2025-10-01 16:35:39,250 [DEBUG] urllib3.connectionpool: Starting new HTTP connection (1): auth-service:8001
2025-10-01 16:35:39,273 [DEBUG] urllib3.connectionpool: http://auth-service:8001 "GET /api/tenant/tenants/09145372-eb5d-40ff-9d93-ca49425a16e6/ HTTP/1.1" 200 428
2025-10-01 16:35:39,275 [INFO] job_applications: Set schema to: proliance
2025-10-01 16:35:39,278 [ERROR] job_applications: Error retrieving job application: relation "job_applications_job_application" does not exist
LINE 1: ...b_applications_job_application"."updated_at" FROM "job_appli...
                                                             ^
Traceback (most recent call last):
  File "/usr/local/lib/python3.11/site-packages/django/db/backends/utils.py", line 105, in _execute
    return self.cursor.execute(sql, params)
           ^^^^^^^^^^^^^^^^^^^^^^^^^^^^^^^^
psycopg2.errors.UndefinedTable: relation "job_applications_job_application" does not exist
LINE 1: ...b_applications_job_application"."updated_at" FROM "job_appli...
                                                             ^


The above exception was the direct cause of the following exception:

Traceback (most recent call last):
  File "/app/job_application/views.py", line 1055, in retrieve
    instance = self.get_object()
               ^^^^^^^^^^^^^^^^^
  File "/usr/local/lib/python3.11/site-packages/rest_framework/generics.py", line 100, in get_object
    obj = get_object_or_404(queryset, **filter_kwargs)
          ^^^^^^^^^^^^^^^^^^^^^^^^^^^^^^^^^^^^^^^^^^^^
  File "/usr/local/lib/python3.11/site-packages/rest_framework/generics.py", line 19, in get_object_or_404
    return _get_object_or_404(queryset, *filter_args, **filter_kwargs)
           ^^^^^^^^^^^^^^^^^^^^^^^^^^^^^^^^^^^^^^^^^^^^^^^^^^^^^^^^^^^
  File "/usr/local/lib/python3.11/site-packages/django/shortcuts.py", line 90, in get_object_or_404
    return queryset.get(*args, **kwargs)
           ^^^^^^^^^^^^^^^^^^^^^^^^^^^^^
  File "/usr/local/lib/python3.11/site-packages/django/db/models/query.py", line 629, in get
    num = len(clone)
          ^^^^^^^^^^
  File "/usr/local/lib/python3.11/site-packages/django/db/models/query.py", line 366, in __len__
    self._fetch_all()
  File "/usr/local/lib/python3.11/site-packages/django/db/models/query.py", line 1949, in _fetch_all
    self._result_cache = list(self._iterable_class(self))
                         ^^^^^^^^^^^^^^^^^^^^^^^^^^^^^^^^
  File "/usr/local/lib/python3.11/site-packages/django/db/models/query.py", line 91, in __iter__
    results = compiler.execute_sql(
              ^^^^^^^^^^^^^^^^^^^^^
  File "/usr/local/lib/python3.11/site-packages/django/db/models/sql/compiler.py", line 1623, in execute_sql
    cursor.execute(sql, params)
  File "/usr/local/lib/python3.11/site-packages/django/db/backends/utils.py", line 122, in execute
    return super().execute(sql, params)
           ^^^^^^^^^^^^^^^^^^^^^^^^^^^^
  File "/usr/local/lib/python3.11/site-packages/django/db/backends/utils.py", line 79, in execute
    return self._execute_with_wrappers(
           ^^^^^^^^^^^^^^^^^^^^^^^^^^^^
  File "/usr/local/lib/python3.11/site-packages/django/db/backends/utils.py", line 92, in _execute_with_wrappers
    return executor(sql, params, many, context)
           ^^^^^^^^^^^^^^^^^^^^^^^^^^^^^^^^^^^^
  File "/usr/local/lib/python3.11/site-packages/django/db/backends/utils.py", line 100, in _execute
    with self.db.wrap_database_errors:
  File "/usr/local/lib/python3.11/site-packages/django/db/utils.py", line 91, in __exit__
    raise dj_exc_value.with_traceback(traceback) from exc_value
  File "/usr/local/lib/python3.11/site-packages/django/db/backends/utils.py", line 105, in _execute
    return self.cursor.execute(sql, params)
           ^^^^^^^^^^^^^^^^^^^^^^^^^^^^^^^^
django.db.utils.ProgrammingError: relation "job_applications_job_application" does not exist
LINE 1: ...b_applications_job_application"."updated_at" FROM "job_appli...
                                                             ^

2025-10-01 16:35:39,283 [ERROR] django.request: Internal Server Error: /api/applications-engine/applications/applications/
2025-10-01 16:35:39,283 [ERROR] django.request: Internal Server Error: /api/applications-engine/applications/applications/
2025-10-01 16:35:49,540 [INFO] job_applications: Entering MicroserviceRS256JWTMiddleware
2025-10-01 16:35:49,542 [INFO] job_applications: Fetching public key from: http://auth-service:8001/api/public-key/1f530d5313654d8781aaab5ea0de2065/?tenant_id=3
2025-10-01 16:35:49,543 [DEBUG] urllib3.connectionpool: Starting new HTTP connection (1): auth-service:8001
2025-10-01 16:35:49,566 [DEBUG] urllib3.connectionpool: http://auth-service:8001 "GET /api/public-key/1f530d5313654d8781aaab5ea0de2065/?tenant_id=3 HTTP/1.1" 200 477
2025-10-01 16:35:49,568 [DEBUG] urllib3.connectionpool: Starting new HTTP connection (1): auth-service:8001
2025-10-01 16:35:49,598 [DEBUG] urllib3.connectionpool: http://auth-service:8001 "GET /api/tenant/tenants/09145372-eb5d-40ff-9d93-ca49425a16e6/ HTTP/1.1" 200 428
2025-10-01 16:35:49,600 [INFO] job_applications: Set schema to: proliance
2025-10-01 16:35:49,625 [INFO] job_applications: Entering MicroserviceRS256JWTMiddleware
2025-10-01 16:35:49,626 [INFO] job_applications: Fetching public key from: http://auth-service:8001/api/public-key/1f530d5313654d8781aaab5ea0de2065/?tenant_id=3
2025-10-01 16:35:49,628 [DEBUG] urllib3.connectionpool: Starting new HTTP connection (1): auth-service:8001
2025-10-01 16:35:49,648 [DEBUG] urllib3.connectionpool: http://auth-service:8001 "GET /api/public-key/1f530d5313654d8781aaab5ea0de2065/?tenant_id=3 HTTP/1.1" 200 477
2025-10-01 16:35:49,650 [DEBUG] urllib3.connectionpool: Starting new HTTP connection (1): auth-service:8001
2025-10-01 16:35:49,673 [DEBUG] urllib3.connectionpool: http://auth-service:8001 "GET /api/tenant/tenants/09145372-eb5d-40ff-9d93-ca49425a16e6/ HTTP/1.1" 200 428
2025-10-01 16:35:49,675 [INFO] job_applications: Set schema to: proliance
2025-10-01 16:35:49,677 [INFO] job_applications: Permission check for AnonymousUser - authenticated: False
2025-10-01 16:35:49,712 [ERROR] django.request: Internal Server Error: /api/applications-engine/applications/
Traceback (most recent call last):
  File "/usr/local/lib/python3.11/site-packages/django/db/backends/utils.py", line 105, in _execute
    return self.cursor.execute(sql, params)
           ^^^^^^^^^^^^^^^^^^^^^^^^^^^^^^^^
psycopg2.errors.UndefinedTable: relation "job_applications_job_application" does not exist
LINE 1: SELECT COUNT(*) AS "__count" FROM "job_applications_job_appl...
                                          ^


The above exception was the direct cause of the following exception:

Traceback (most recent call last):
  File "/usr/local/lib/python3.11/site-packages/django/core/handlers/exception.py", line 55, in inner
    response = get_response(request)
               ^^^^^^^^^^^^^^^^^^^^^
  File "/usr/local/lib/python3.11/site-packages/django/core/handlers/base.py", line 197, in _get_response
    response = wrapped_callback(request, *callback_args, **callback_kwargs)
               ^^^^^^^^^^^^^^^^^^^^^^^^^^^^^^^^^^^^^^^^^^^^^^^^^^^^^^^^^^^^
  File "/usr/local/lib/python3.11/site-packages/django/views/decorators/csrf.py", line 65, in _view_wrapper
    return view_func(request, *args, **kwargs)
           ^^^^^^^^^^^^^^^^^^^^^^^^^^^^^^^^^^^
  File "/usr/local/lib/python3.11/site-packages/django/views/generic/base.py", line 105, in view
    return self.dispatch(request, *args, **kwargs)
           ^^^^^^^^^^^^^^^^^^^^^^^^^^^^^^^^^^^^^^^
  File "/usr/local/lib/python3.11/site-packages/rest_framework/views.py", line 515, in dispatch
    response = self.handle_exception(exc)
               ^^^^^^^^^^^^^^^^^^^^^^^^^^
  File "/usr/local/lib/python3.11/site-packages/rest_framework/views.py", line 475, in handle_exception
    self.raise_uncaught_exception(exc)
  File "/usr/local/lib/python3.11/site-packages/rest_framework/views.py", line 486, in raise_uncaught_exception
    raise exc
  File "/usr/local/lib/python3.11/site-packages/rest_framework/views.py", line 512, in dispatch
    response = handler(request, *args, **kwargs)
               ^^^^^^^^^^^^^^^^^^^^^^^^^^^^^^^^^
  File "/usr/local/lib/python3.11/site-packages/rest_framework/generics.py", line 243, in get
    return self.list(request, *args, **kwargs)
           ^^^^^^^^^^^^^^^^^^^^^^^^^^^^^^^^^^^
  File "/usr/local/lib/python3.11/site-packages/rest_framework/mixins.py", line 40, in list
    page = self.paginate_queryset(queryset)
           ^^^^^^^^^^^^^^^^^^^^^^^^^^^^^^^^
  File "/usr/local/lib/python3.11/site-packages/rest_framework/generics.py", line 175, in paginate_queryset
    return self.paginator.paginate_queryset(queryset, self.request, view=self)
           ^^^^^^^^^^^^^^^^^^^^^^^^^^^^^^^^^^^^^^^^^^^^^^^^^^^^^^^^^^^^^^^^^^^
  File "/usr/local/lib/python3.11/site-packages/rest_framework/pagination.py", line 211, in paginate_queryset
    self.page = paginator.page(page_number)
                ^^^^^^^^^^^^^^^^^^^^^^^^^^^
  File "/usr/local/lib/python3.11/site-packages/django/core/paginator.py", line 89, in page
    number = self.validate_number(number)
             ^^^^^^^^^^^^^^^^^^^^^^^^^^^^
  File "/usr/local/lib/python3.11/site-packages/django/core/paginator.py", line 70, in validate_number
    if number > self.num_pages:
                ^^^^^^^^^^^^^^
  File "/usr/local/lib/python3.11/site-packages/django/utils/functional.py", line 47, in __get__
    res = instance.__dict__[self.name] = self.func(instance)
                                         ^^^^^^^^^^^^^^^^^^^
  File "/usr/local/lib/python3.11/site-packages/django/core/paginator.py", line 116, in num_pages
    if self.count == 0 and not self.allow_empty_first_page:
       ^^^^^^^^^^
  File "/usr/local/lib/python3.11/site-packages/django/utils/functional.py", line 47, in __get__
    res = instance.__dict__[self.name] = self.func(instance)
                                         ^^^^^^^^^^^^^^^^^^^
  File "/usr/local/lib/python3.11/site-packages/django/core/paginator.py", line 110, in count
    return c()
           ^^^
  File "/usr/local/lib/python3.11/site-packages/django/db/models/query.py", line 604, in count
    return self.query.get_count(using=self.db)
           ^^^^^^^^^^^^^^^^^^^^^^^^^^^^^^^^^^^
  File "/usr/local/lib/python3.11/site-packages/django/db/models/sql/query.py", line 644, in get_count
    return obj.get_aggregation(using, {"__count": Count("*")})["__count"]
           ^^^^^^^^^^^^^^^^^^^^^^^^^^^^^^^^^^^^^^^^^^^^^^^^^^^
  File "/usr/local/lib/python3.11/site-packages/django/db/models/sql/query.py", line 626, in get_aggregation
    result = compiler.execute_sql(SINGLE)
             ^^^^^^^^^^^^^^^^^^^^^^^^^^^^
  File "/usr/local/lib/python3.11/site-packages/django/db/models/sql/compiler.py", line 1623, in execute_sql
    cursor.execute(sql, params)
  File "/usr/local/lib/python3.11/site-packages/django/db/backends/utils.py", line 122, in execute
    return super().execute(sql, params)
           ^^^^^^^^^^^^^^^^^^^^^^^^^^^^
  File "/usr/local/lib/python3.11/site-packages/django/db/backends/utils.py", line 79, in execute
    return self._execute_with_wrappers(
           ^^^^^^^^^^^^^^^^^^^^^^^^^^^^
  File "/usr/local/lib/python3.11/site-packages/django/db/backends/utils.py", line 92, in _execute_with_wrappers
    return executor(sql, params, many, context)
           ^^^^^^^^^^^^^^^^^^^^^^^^^^^^^^^^^^^^
  File "/usr/local/lib/python3.11/site-packages/django/db/backends/utils.py", line 100, in _execute
    with self.db.wrap_database_errors:
  File "/usr/local/lib/python3.11/site-packages/django/db/utils.py", line 91, in __exit__
    raise dj_exc_value.with_traceback(traceback) from exc_value
  File "/usr/local/lib/python3.11/site-packages/django/db/backends/utils.py", line 105, in _execute
    return self.cursor.execute(sql, params)
           ^^^^^^^^^^^^^^^^^^^^^^^^^^^^^^^^
django.db.utils.ProgrammingError: relation "job_applications_job_application" does not exist
LINE 1: SELECT COUNT(*) AS "__count" FROM "job_applications_job_appl...
                                          ^

2025-10-01 16:35:49,712 [ERROR] django.request: Internal Server Error: /api/applications-engine/applications/
Traceback (most recent call last):
  File "/usr/local/lib/python3.11/site-packages/django/db/backends/utils.py", line 105, in _execute
    return self.cursor.execute(sql, params)
           ^^^^^^^^^^^^^^^^^^^^^^^^^^^^^^^^
psycopg2.errors.UndefinedTable: relation "job_applications_job_application" does not exist
LINE 1: SELECT COUNT(*) AS "__count" FROM "job_applications_job_appl...
                                          ^


The above exception was the direct cause of the following exception:

Traceback (most recent call last):
  File "/usr/local/lib/python3.11/site-packages/django/core/handlers/exception.py", line 55, in inner
    response = get_response(request)
               ^^^^^^^^^^^^^^^^^^^^^
  File "/usr/local/lib/python3.11/site-packages/django/core/handlers/base.py", line 197, in _get_response
    response = wrapped_callback(request, *callback_args, **callback_kwargs)
               ^^^^^^^^^^^^^^^^^^^^^^^^^^^^^^^^^^^^^^^^^^^^^^^^^^^^^^^^^^^^
  File "/usr/local/lib/python3.11/site-packages/django/views/decorators/csrf.py", line 65, in _view_wrapper
    return view_func(request, *args, **kwargs)
           ^^^^^^^^^^^^^^^^^^^^^^^^^^^^^^^^^^^
  File "/usr/local/lib/python3.11/site-packages/django/views/generic/base.py", line 105, in view
    return self.dispatch(request, *args, **kwargs)
           ^^^^^^^^^^^^^^^^^^^^^^^^^^^^^^^^^^^^^^^
  File "/usr/local/lib/python3.11/site-packages/rest_framework/views.py", line 515, in dispatch
    response = self.handle_exception(exc)
               ^^^^^^^^^^^^^^^^^^^^^^^^^^
  File "/usr/local/lib/python3.11/site-packages/rest_framework/views.py", line 475, in handle_exception
    self.raise_uncaught_exception(exc)
  File "/usr/local/lib/python3.11/site-packages/rest_framework/views.py", line 486, in raise_uncaught_exception
    raise exc
  File "/usr/local/lib/python3.11/site-packages/rest_framework/views.py", line 512, in dispatch
    response = handler(request, *args, **kwargs)
               ^^^^^^^^^^^^^^^^^^^^^^^^^^^^^^^^^
  File "/usr/local/lib/python3.11/site-packages/rest_framework/generics.py", line 243, in get
    return self.list(request, *args, **kwargs)
           ^^^^^^^^^^^^^^^^^^^^^^^^^^^^^^^^^^^
  File "/usr/local/lib/python3.11/site-packages/rest_framework/mixins.py", line 40, in list
    page = self.paginate_queryset(queryset)
           ^^^^^^^^^^^^^^^^^^^^^^^^^^^^^^^^
  File "/usr/local/lib/python3.11/site-packages/rest_framework/generics.py", line 175, in paginate_queryset
    return self.paginator.paginate_queryset(queryset, self.request, view=self)
           ^^^^^^^^^^^^^^^^^^^^^^^^^^^^^^^^^^^^^^^^^^^^^^^^^^^^^^^^^^^^^^^^^^^
  File "/usr/local/lib/python3.11/site-packages/rest_framework/pagination.py", line 211, in paginate_queryset
    self.page = paginator.page(page_number)
                ^^^^^^^^^^^^^^^^^^^^^^^^^^^
  File "/usr/local/lib/python3.11/site-packages/django/core/paginator.py", line 89, in page
    number = self.validate_number(number)
             ^^^^^^^^^^^^^^^^^^^^^^^^^^^^
  File "/usr/local/lib/python3.11/site-packages/django/core/paginator.py", line 70, in validate_number
    if number > self.num_pages:
                ^^^^^^^^^^^^^^
  File "/usr/local/lib/python3.11/site-packages/django/utils/functional.py", line 47, in __get__
    res = instance.__dict__[self.name] = self.func(instance)
                                         ^^^^^^^^^^^^^^^^^^^
  File "/usr/local/lib/python3.11/site-packages/django/core/paginator.py", line 116, in num_pages
    if self.count == 0 and not self.allow_empty_first_page:
       ^^^^^^^^^^
  File "/usr/local/lib/python3.11/site-packages/django/utils/functional.py", line 47, in __get__
    res = instance.__dict__[self.name] = self.func(instance)
                                         ^^^^^^^^^^^^^^^^^^^
  File "/usr/local/lib/python3.11/site-packages/django/core/paginator.py", line 110, in count
    return c()
           ^^^
  File "/usr/local/lib/python3.11/site-packages/django/db/models/query.py", line 604, in count
    return self.query.get_count(using=self.db)
           ^^^^^^^^^^^^^^^^^^^^^^^^^^^^^^^^^^^
  File "/usr/local/lib/python3.11/site-packages/django/db/models/sql/query.py", line 644, in get_count
    return obj.get_aggregation(using, {"__count": Count("*")})["__count"]
           ^^^^^^^^^^^^^^^^^^^^^^^^^^^^^^^^^^^^^^^^^^^^^^^^^^^
  File "/usr/local/lib/python3.11/site-packages/django/db/models/sql/query.py", line 626, in get_aggregation
    result = compiler.execute_sql(SINGLE)
             ^^^^^^^^^^^^^^^^^^^^^^^^^^^^
  File "/usr/local/lib/python3.11/site-packages/django/db/models/sql/compiler.py", line 1623, in execute_sql
    cursor.execute(sql, params)
  File "/usr/local/lib/python3.11/site-packages/django/db/backends/utils.py", line 122, in execute
    return super().execute(sql, params)
           ^^^^^^^^^^^^^^^^^^^^^^^^^^^^
  File "/usr/local/lib/python3.11/site-packages/django/db/backends/utils.py", line 79, in execute
    return self._execute_with_wrappers(
           ^^^^^^^^^^^^^^^^^^^^^^^^^^^^
  File "/usr/local/lib/python3.11/site-packages/django/db/backends/utils.py", line 92, in _execute_with_wrappers
    return executor(sql, params, many, context)
           ^^^^^^^^^^^^^^^^^^^^^^^^^^^^^^^^^^^^
  File "/usr/local/lib/python3.11/site-packages/django/db/backends/utils.py", line 100, in _execute
    with self.db.wrap_database_errors:
  File "/usr/local/lib/python3.11/site-packages/django/db/utils.py", line 91, in __exit__
    raise dj_exc_value.with_traceback(traceback) from exc_value
  File "/usr/local/lib/python3.11/site-packages/django/db/backends/utils.py", line 105, in _execute
    return self.cursor.execute(sql, params)
           ^^^^^^^^^^^^^^^^^^^^^^^^^^^^^^^^
django.db.utils.ProgrammingError: relation "job_applications_job_application" does not exist
LINE 1: SELECT COUNT(*) AS "__count" FROM "job_applications_job_appl...
                                          ^

2025-10-01 16:35:58,920 [INFO] job_applications.settings: Logging configuration applied successfully
2025-10-01 16:35:58,921 [DEBUG] environ.environ: get 'CELERY_BROKER_URL' casted as 'None' with default 'redis://job_app_redis:6379/0'
2025-10-01 16:35:58,921 [DEBUG] environ.environ: get 'CELERY_RESULT_BACKEND' casted as 'None' with default 'redis://job_app_redis:6379/0'
2025-10-01 16:36:34,231 [INFO] job_applications.settings: Logging configuration applied successfully
2025-10-01 16:36:34,232 [DEBUG] environ.environ: get 'CELERY_BROKER_URL' casted as 'None' with default 'redis://job_app_redis:6379/0'
2025-10-01 16:36:34,234 [DEBUG] environ.environ: get 'CELERY_RESULT_BACKEND' casted as 'None' with default 'redis://job_app_redis:6379/0'
2025-10-01 16:37:43,090 [INFO] job_applications: Entering MicroserviceRS256JWTMiddleware
2025-10-01 16:37:43,092 [INFO] job_applications: Fetching public key from: http://auth-service:8001/api/public-key/1f530d5313654d8781aaab5ea0de2065/?tenant_id=3
2025-10-01 16:37:43,095 [DEBUG] urllib3.connectionpool: Starting new HTTP connection (1): auth-service:8001
2025-10-01 16:37:43,133 [DEBUG] urllib3.connectionpool: http://auth-service:8001 "GET /api/public-key/1f530d5313654d8781aaab5ea0de2065/?tenant_id=3 HTTP/1.1" 200 477
2025-10-01 16:37:43,136 [DEBUG] urllib3.connectionpool: Starting new HTTP connection (1): auth-service:8001
2025-10-01 16:37:43,159 [DEBUG] urllib3.connectionpool: http://auth-service:8001 "GET /api/tenant/tenants/09145372-eb5d-40ff-9d93-ca49425a16e6/ HTTP/1.1" 200 428
2025-10-01 16:37:43,162 [INFO] job_applications: Set schema to: proliance
2025-10-01 16:37:43,181 [INFO] job_applications: Entering MicroserviceRS256JWTMiddleware
2025-10-01 16:37:43,182 [INFO] job_applications: Fetching public key from: http://auth-service:8001/api/public-key/1f530d5313654d8781aaab5ea0de2065/?tenant_id=3
2025-10-01 16:37:43,184 [DEBUG] urllib3.connectionpool: Starting new HTTP connection (1): auth-service:8001
2025-10-01 16:37:43,204 [DEBUG] urllib3.connectionpool: http://auth-service:8001 "GET /api/public-key/1f530d5313654d8781aaab5ea0de2065/?tenant_id=3 HTTP/1.1" 200 477
2025-10-01 16:37:43,207 [DEBUG] urllib3.connectionpool: Starting new HTTP connection (1): auth-service:8001
2025-10-01 16:37:43,231 [DEBUG] urllib3.connectionpool: http://auth-service:8001 "GET /api/tenant/tenants/09145372-eb5d-40ff-9d93-ca49425a16e6/ HTTP/1.1" 200 428
2025-10-01 16:37:43,233 [INFO] job_applications: Set schema to: proliance
2025-10-01 16:37:43,235 [INFO] job_applications: Permission check for AnonymousUser - authenticated: False
